Workbook

Sheet 使い方
A1: 使い方
A2: 【入力シート】
A3: 派遣先管理台帳 | B3: システム受注番号はハイフンなしで入力
B4: 他の使い方は割愛します。
A6: 交通費明細 | B6: 月日～日当までは手入力
B7: 欄外の案件コードに入力されたコードで請求内容入力シートの交通費(通常)、交通費(保守)欄に自動集計します。
B8: (コードはハイフンなしで入力してください。)
A10: 請求内容入力シート | B10: 日付は請求日付を入力。
B11: 作業(通常)、作業(保守)は案件コード～金額、コードを入力。(案件コードはハイフンなし)
B12: 他の列は自動計算されます。
B13: 交通費(通常)、交通費(保守)は案件コード～案件名、コードを入力。(案件コードはハイフンなし)
B14: 他の列は自動計算されます。
A16: パラメータ
A19: 202102修正版
A20: 派遣先管理台帳 | B20: 以下のセルは会社/個人ごとに修正してください。 | G20: SMJ派遣責任者検印欄を変更する場合は数式を修正してください。
B37: 超過時間の算出式は会社ごとに異なるので、必ず自社の算出式に修正してください。
B38: 単価が深夜、休出など種類によって異なる場合も、必ず数式を修正してください。

Sheet 派遣管理台帳
A1: ○１部コピーし２部共捺印、原紙は請求書添付・コピーは派遣元控（写しを派遣先責任者保管） | G1: 派遣先管理台帳－４（就業管理台帳）（20日締め用） | Y1: =MONTH(Q3) -> 9 | AU1: 時間内 | AV1: 7.75 | AW1: B | AX1: C
U2: ①作成日 | V2: =H3 -> 46255 | AE2: A | AU2: 超過 | AV2: 0.75 | AW2: 0.70833333 | AX2: 0.79166667
G3: ②期間 | H3: 46255 | Q3: =DATE(YEAR(H3),MONTH(H3)+1,20) -> 46285 | U3: 組織単位の抵触日 | V3: ー年 ー月 ー日 | AE3: B | AV3: 0.91666667
B4: ③派遣先情報 | R4: ④派遣元情報 | AE4: C | AU4: 深夜超過 | AV4: 0.9375
B5: 派遣先事業所名 | F5: シャープマーケティングジャパン株式会社 | R5: 派遣労働者氏名 | U5: =パラメータ!B4 -> グエン ホン ソン | AE5: D | AT5: ★ | AU5: 単価 | AV5: 2500
B6: 派遣先事業所住所 | F6: 千葉県千葉市美浜区中瀬 1-9-2 シャープ幕張ビル | R6: 派遣元事業主名 | U6: 株式会社ＶＴＩジャパン | AE6: E | AT6: ★ | AU6: 基本金額 | AV6: 400000
B7: 就業場所 | F7: 18階 ビジネスソリューション社 ソリューション開発統轄部 企業システム開発部 第2開発センター | R7: 派遣元事業所名 | AU7: 昼開始 | AV7: 0.47916667
B8: 組織単位 | F8: ソリューション開発統轄部 企業システム開発部 部長 | R8: 派遣元事業所住所 | U8: 東京都新宿区片町4-3 曙橋SHKビル5階 | AU8: 控除 | AV8: 20
B9: 派遣先責任者 | F9: 鎌田 克 | R9: 派遣元責任者 | U9: チャン・スアン・コイ | Z9: ≪システム開発部門用≫ | AU9: 超過 | AV9: 20
B10: 業務に伴う責任の程度 | F10: 役職なし
B12: 日付 | D12: ⑤所定休日 | E12: 就業時間 | H12: 時間内 勤務(H) | J12: 0.375 | K12: 0.75 | L12: 0.91666667 | M12: 0.375 | N12: 0.73958333 | O12: 超過勤務 | Q12: 休日勤務 | S12: 当月時間外 休日就業時間 | T12: 不就業 | U12: 不就業 代休・欠勤 (H) | V12: 業務内容/場所 1）当日行った業務内容を記載 2）上記就業場所以外で就業した場合、その場所を記載 | X12: 選択勤務区分 | Y12: ＳＭＪ 責任者 検印欄 | AC12: 当 月 作 業 内 容 | AS12: 合計 ﾁｪｯｸ
B13: 月日 | C13: 曜 | E13: 始業時刻 | F13: 終業時刻 | G13: 昼休憩・ 時間外労働時休憩 | I13: 実働時間 | J13: 普通残業 | K13: 普通残業 | L13: 深夜残業 | M13: 遅刻 | N13: 早退 | O13: 普通 (H) | P13: 深夜 (H) | Q13: 普通 (H) | R13: 深夜 (H) | S13: 累計 | T13: 遅刻早退 (H) | AC13: ｼｽﾃﾑ 受注番号 | AD13: 顧客名 （ｼｽﾃﾑ名称） | AE13: 作業 時間 | AF13: ｼｽﾃﾑ 受注番号 | AG13: 顧客名 （ｼｽﾃﾑ名称） | AH13: 作業 時間 | AI13: ｼｽﾃﾑ 受注番号 | AJ13: 顧客名 （ｼｽﾃﾑ名称） | AK13: 作業 時間 | AL13: ｼｽﾃﾑ 受注番号 | AM13: 顧客名 （ｼｽﾃﾑ名称） | AN13: 作業 時間 | AO13: ｼｽﾃﾑ 受注番号 | AP13: 顧客名 （ｼｽﾃﾑ名称） | AQ13: 作業 時間 | AR13: 合計 時間 | AU13: 作業時間 | AV13: 普通 残業 | AW13: 普通 深夜 | AX13: 休日 | AY13: 休日 深夜 | AZ13: 超過 START
B14: =IF(H3="","",H3) -> 46255 | C14: =IF(B14="","",CHOOSE(WEEKDAY(B14),"日","月","火","水","木","金","土")) -> 金 | AR14: =SUM(AE14,AH14,AK14,AN14,AQ14) -> 0 | AS14: =IF(AR14=SUM($H14,$O14,$P14,$Q14,$R14,-$U14,-$T14),"合","不") -> 合
B15: =IF(B14="","",IF(B14+1>Q$3,"",B14+1)) -> 46256 | C15: =IF(B15="","",CHOOSE(WEEKDAY(B15),"日","月","火","水","木","金","土")) -> 土 | D15: * | AR15: =SUM(AE15,AH15,AK15,AN15,AQ15) -> 0 | AS15: =IF(AR15=SUM($H15,$O15,$P15,$Q15,$R15,-$U15,-$T15),"合","不") -> 合
B16: =IF(B15="","",IF(B15+1>Q$3,"",B15+1)) -> 46257 | C16: =IF(B16="","",CHOOSE(WEEKDAY(B16),"日","月","火","水","木","金","土")) -> 日 | D16: * | AR16: =SUM(AE16,AH16,AK16,AN16,AQ16) -> 0 | AS16: =IF(AR16=SUM($H16,$O16,$P16,$Q16,$R16,-$U16,-$T16),"合","不") -> 合
B17: =IF(B16="","",IF(B16+1>Q$3,"",B16+1)) -> 46258 | C17: =IF(B17="","",CHOOSE(WEEKDAY(B17),"日","月","火","水","木","金","土")) -> 月 | AR17: =SUM(AE17,AH17,AK17,AN17,AQ17) -> 0 | AS17: =IF(AR17=SUM($H17,$O17,$P17,$Q17,$R17,-$U17,-$T17),"合","不") -> 合
B18: =IF(B17="","",IF(B17+1>Q$3,"",B17+1)) -> 46259 | C18: =IF(B18="","",CHOOSE(WEEKDAY(B18),"日","月","火","水","木","金","土")) -> 火 | AR18: =SUM(AE18,AH18,AK18,AN18,AQ18) -> 0 | AS18: =IF(AR18=SUM($H18,$O18,$P18,$Q18,$R18,-$U18,-$T18),"合","不") -> 合
B19: =IF(B18="","",IF(B18+1>Q$3,"",B18+1)) -> 46260 | C19: =IF(B19="","",CHOOSE(WEEKDAY(B19),"日","月","火","水","木","金","土")) -> 水 | AR19: =SUM(AE19,AH19,AK19,AN19,AQ19) -> 0 | AS19: =IF(AR19=SUM($H19,$O19,$P19,$Q19,$R19,-$U19,-$T19),"合","不") -> 合
B20: =IF(B19="","",IF(B19+1>Q$3,"",B19+1)) -> 46261 | C20: =IF(B20="","",CHOOSE(WEEKDAY(B20),"日","月","火","水","木","金","土")) -> 木 | AR20: =SUM(AE20,AH20,AK20,AN20,AQ20) -> 0 | AS20: =IF(AR20=SUM($H20,$O20,$P20,$Q20,$R20,-$U20,-$T20),"合","不") -> 合
B21: =IF(B20="","",IF(B20+1>Q$3,"",B20+1)) -> 46262 | C21: =IF(B21="","",CHOOSE(WEEKDAY(B21),"日","月","火","水","木","金","土")) -> 金 | AR21: =SUM(AE21,AH21,AK21,AN21,AQ21) -> 0 | AS21: =IF(AR21=SUM($H21,$O21,$P21,$Q21,$R21,-$U21,-$T21),"合","不") -> 合
B22: =IF(B21="","",IF(B21+1>Q$3,"",B21+1)) -> 46263 | C22: =IF(B22="","",CHOOSE(WEEKDAY(B22),"日","月","火","水","木","金","土")) -> 土 | D22: * | AR22: =SUM(AE22,AH22,AK22,AN22,AQ22) -> 0 | AS22: =IF(AR22=SUM($H22,$O22,$P22,$Q22,$R22,-$U22,-$T22),"合","不") -> 合
B23: =IF(B22="","",IF(B22+1>Q$3,"",B22+1)) -> 46264 | C23: =IF(B23="","",CHOOSE(WEEKDAY(B23),"日","月","火","水","木","金","土")) -> 日 | D23: * | AR23: =SUM(AE23,AH23,AK23,AN23,AQ23) -> 0 | AS23: =IF(AR23=SUM($H23,$O23,$P23,$Q23,$R23,-$U23,-$T23),"合","不") -> 合
B24: =IF(B23="","",IF(B23+1>Q$3,"",B23+1)) -> 46265 | C24: =IF(B24="","",CHOOSE(WEEKDAY(B24),"日","月","火","水","木","金","土")) -> 月 | AR24: =SUM(AE24,AH24,AK24,AN24,AQ24) -> 0 | AS24: =IF(AR24=SUM($H24,$O24,$P24,$Q24,$R24,-$U24,-$T24),"合","不") -> 合
B25: =IF(B24="","",IF(B24+1>Q$3,"",B24+1)) -> 46266 | C25: =IF(B25="","",CHOOSE(WEEKDAY(B25),"日","月","火","水","木","金","土")) -> 火 | H25: 7.75 | O25: =IF(AV25<>"",HOUR(AV25)+MINUTE(AV25)/60,"") | P25: =IF(AW25<>"",HOUR(AW25)+MINUTE(AW25)/60,"") | Q25: =IF(AX25<>"",HOUR(AX25)+MINUTE(AX25)/60,"") | R25: =IF(AY25<>"",HOUR(AY25)+MINUTE(AY25)/60,"") | U25: 7.75 | V25: 欠勤 | Y25: 陳 | AR25: =SUM(AE25,AH25,AK25,AN25,AQ25) -> 0 | AS25: =IF(AR25=SUM($H25,$O25,$P25,$Q25,$R25,-$U25,-$T25),"合","不") -> 合 | AU25: =IF(AND(F25<>"",E25<>"",G25<>""),F25-E25-G25,"") | AV25: =IF(AND(D25="",AU25<>""),IF(F25>$AZ25,IF(F25>$AV$3,$AV$3-$AZ25,F25-$AZ25),""),"") | AW25: =IF(AND(D25="",F25>$AV$4),F25-$AV$4,"") | AX25: =IF(AND(D25="*",AU25<>""),AU25-IF(AY25<>"",AY25,0),"") | AY25: =IF(AND(D25="*",F25>$AV$4),F25-$AV$4,"") | AZ25: =IF(X25="B",$AW$2,IF(X25="C",$AX$2,$AV$2)) -> 0.75
B26: =IF(B25="","",IF(B25+1>Q$3,"",B25+1)) -> 46267 | C26: =IF(B26="","",CHOOSE(WEEKDAY(B26),"日","月","火","水","木","金","土")) -> 水 | E26: 0.375 | F26: 0.73958333 | G26: 0.041666667 | H26: 7.75 | O26: =IF(AV26<>"",HOUR(AV26)+MINUTE(AV26)/60,"") | P26: =IF(AW26<>"",HOUR(AW26)+MINUTE(AW26)/60,"") | Q26: =IF(AX26<>"",HOUR(AX26)+MINUTE(AX26)/60,"") | R26: =IF(AY26<>"",HOUR(AY26)+MINUTE(AY26)/60,"") | V26: 作業環境の準備、設定 | Y26: 陳 | AC26: 387605022 | AD26: タブレットPOS端末アプリ | AE26: =SUM(H26,O26:R26)-SUM(T26:U26,AH26,AK26,AN26,AQ26) -> 7.75 | AR26: =SUM(AE26,AH26,AK26,AN26,AQ26) -> 7.75 | AS26: =IF(AR26=SUM($H26,$O26,$P26,$Q26,$R26,-$U26,-$T26),"合","不") -> 合 | AU26: =IF(AND(F26<>"",E26<>"",G26<>""),F26-E26-G26,"") -> 0.32291667 | AV26: =IF(AND(D26="",AU26<>""),IF(F26>$AZ26,IF(F26>$AV$3,$AV$3-$AZ26,F26-$AZ26),""),"") | AW26: =IF(AND(D26="",F26>$AV$4),F26-$AV$4,"") | AX26: =IF(AND(D26="*",AU26<>""),AU26-IF(AY26<>"",AY26,0),"") | AY26: =IF(AND(D26="*",F26>$AV$4),F26-$AV$4,"") | AZ26: =IF(X26="B",$AW$2,IF(X26="C",$AX$2,$AV$2)) -> 0.75
B27: =IF(B26="","",IF(B26+1>Q$3,"",B26+1)) -> 46268 | C27: =IF(B27="","",CHOOSE(WEEKDAY(B27),"日","月","火","水","木","金","土")) -> 木 | E27: 0.375 | F27: 0.73958333 | G27: 0.041666667 | H27: 7.75 | O27: =IF(AV27<>"",HOUR(AV27)+MINUTE(AV27)/60,"") | P27: =IF(AW27<>"",HOUR(AW27)+MINUTE(AW27)/60,"") | Q27: =IF(AX27<>"",HOUR(AX27)+MINUTE(AX27)/60,"") | R27: =IF(AY27<>"",HOUR(AY27)+MINUTE(AY27)/60,"") | S27: =IF(E27="","",SUM($O$14:O27)+SUM($P$14:P27)+SUM($Q$14:Q27)+SUM($R$14:R27)) -> 0 | V27: 開発環境の設定、接続確認 | Y27: 陳 | AC27: 387605022 | AD27: タブレットPOS端末アプリ | AE27: =SUM(H27,O27:R27)-SUM(T27:U27,AH27,AK27,AN27,AQ27) -> 7.75 | AR27: =SUM(AE27,AH27,AK27,AN27,AQ27) -> 7.75 | AS27: =IF(AR27=SUM($H27,$O27,$P27,$Q27,$R27,-$U27,-$T27),"合","不") -> 合 | AU27: =IF(AND(F27<>"",E27<>"",G27<>""),F27-E27-G27,"") -> 0.32291667 | AV27: =IF(AND(D27="",AU27<>""),IF(F27>$AZ27,IF(F27>$AV$3,$AV$3-$AZ27,F27-$AZ27),""),"") | AW27: =IF(AND(D27="",F27>$AV$4),F27-$AV$4,"") | AX27: =IF(AND(D27="*",AU27<>""),AU27-IF(AY27<>"",AY27,0),"") | AY27: =IF(AND(D27="*",F27>$AV$4),F27-$AV$4,"") | AZ27: =IF(X27="B",$AW$2,IF(X27="C",$AX$2,$AV$2)) -> 0.75
B28: =IF(B27="","",IF(B27+1>Q$3,"",B27+1)) -> 46269 | C28: =IF(B28="","",CHOOSE(WEEKDAY(B28),"日","月","火","水","木","金","土")) -> 金 | E28: 0.375 | F28: 0.73958333 | G28: 0.041666667 | H28: 7.75 | O28: =IF(AV28<>"",HOUR(AV28)+MINUTE(AV28)/60,"") | P28: =IF(AW28<>"",HOUR(AW28)+MINUTE(AW28)/60,"") | Q28: =IF(AX28<>"",HOUR(AX28)+MINUTE(AX28)/60,"") | R28: =IF(AY28<>"",HOUR(AY28)+MINUTE(AY28)/60,"") | S28: =IF(E28="","",SUM($O$14:O28)+SUM($P$14:P28)+SUM($Q$14:Q28)+SUM($R$14:R28)) -> 0 | V28: 作業環境の設定、確認 | Y28: 陳 | AC28: 387605022 | AD28: タブレットPOS端末アプリ | AE28: =SUM(H28,O28:R28)-SUM(T28:U28,AH28,AK28,AN28,AQ28) -> 7.75 | AR28: =SUM(AE28,AH28,AK28,AN28,AQ28) -> 7.75 | AS28: =IF(AR28=SUM($H28,$O28,$P28,$Q28,$R28,-$U28,-$T28),"合","不") -> 合 | AU28: =IF(AND(F28<>"",E28<>"",G28<>""),F28-E28-G28,"") -> 0.32291667 | AV28: =IF(AND(D28="",AU28<>""),IF(F28>$AZ28,IF(F28>$AV$3,$AV$3-$AZ28,F28-$AZ28),""),"") | AW28: =IF(AND(D28="",F28>$AV$4),F28-$AV$4,"") | AX28: =IF(AND(D28="*",AU28<>""),AU28-IF(AY28<>"",AY28,0),"") | AY28: =IF(AND(D28="*",F28>$AV$4),F28-$AV$4,"") | AZ28: =IF(X28="B",$AW$2,IF(X28="C",$AX$2,$AV$2)) -> 0.75
B29: =IF(B28="","",IF(B28+1>Q$3,"",B28+1)) -> 46270 | C29: =IF(B29="","",CHOOSE(WEEKDAY(B29),"日","月","火","水","木","金","土")) -> 土 | D29: * | O29: =IF(AV29<>"",HOUR(AV29)+MINUTE(AV29)/60,"") | P29: =IF(AW29<>"",HOUR(AW29)+MINUTE(AW29)/60,"") | Q29: =IF(AX29<>"",HOUR(AX29)+MINUTE(AX29)/60,"") | R29: =IF(AY29<>"",HOUR(AY29)+MINUTE(AY29)/60,"") | S29: =IF(E29="","",SUM($O$14:O29)+SUM($P$14:P29)+SUM($Q$14:Q29)+SUM($R$14:R29)) | AR29: =SUM(AE29,AH29,AK29,AN29,AQ29) -> 0 | AS29: =IF(AR29=SUM($H29,$O29,$P29,$Q29,$R29,-$U29,-$T29),"合","不") -> 合 | AU29: =IF(AND(F29<>"",E29<>"",G29<>""),F29-E29-G29,"") | AV29: =IF(AND(D29="",AU29<>""),IF(F29>$AZ29,IF(F29>$AV$3,$AV$3-$AZ29,F29-$AZ29),""),"") | AW29: =IF(AND(D29="",F29>$AV$4),F29-$AV$4,"") | AX29: =IF(AND(D29="*",AU29<>""),AU29-IF(AY29<>"",AY29,0),"") | AY29: =IF(AND(D29="*",F29>$AV$4),F29-$AV$4,"") | AZ29: =IF(X29="B",$AW$2,IF(X29="C",$AX$2,$AV$2)) -> 0.75
B30: =IF(B29="","",IF(B29+1>Q$3,"",B29+1)) -> 46271 | C30: =IF(B30="","",CHOOSE(WEEKDAY(B30),"日","月","火","水","木","金","土")) -> 日 | D30: * | O30: =IF(AV30<>"",HOUR(AV30)+MINUTE(AV30)/60,"") | P30: =IF(AW30<>"",HOUR(AW30)+MINUTE(AW30)/60,"") | Q30: =IF(AX30<>"",HOUR(AX30)+MINUTE(AX30)/60,"") | R30: =IF(AY30<>"",HOUR(AY30)+MINUTE(AY30)/60,"") | S30: =IF(E30="","",SUM($O$14:O30)+SUM($P$14:P30)+SUM($Q$14:Q30)+SUM($R$14:R30)) | AR30: =SUM(AE30,AH30,AK30,AN30,AQ30) -> 0 | AS30: =IF(AR30=SUM($H30,$O30,$P30,$Q30,$R30,-$U30,-$T30),"合","不") -> 合 | AU30: =IF(AND(F30<>"",E30<>"",G30<>""),F30-E30-G30,"") | AV30: =IF(AND(D30="",AU30<>""),IF(F30>$AZ30,IF(F30>$AV$3,$AV$3-$AZ30,F30-$AZ30),""),"") | AW30: =IF(AND(D30="",F30>$AV$4),F30-$AV$4,"") | AX30: =IF(AND(D30="*",AU30<>""),AU30-IF(AY30<>"",AY30,0),"") | AY30: =IF(AND(D30="*",F30>$AV$4),F30-$AV$4,"") | AZ30: =IF(X30="B",$AW$2,IF(X30="C",$AX$2,$AV$2)) -> 0.75
B31: =IF(B30="","",IF(B30+1>Q$3,"",B30+1)) -> 46272 | C31: =IF(B31="","",CHOOSE(WEEKDAY(B31),"日","月","火","水","木","金","土")) -> 月 | H31: 7.75 | O31: =IF(AV31<>"",HOUR(AV31)+MINUTE(AV31)/60,"") | P31: =IF(AW31<>"",HOUR(AW31)+MINUTE(AW31)/60,"") | Q31: =IF(AX31<>"",HOUR(AX31)+MINUTE(AX31)/60,"") | R31: =IF(AY31<>"",HOUR(AY31)+MINUTE(AY31)/60,"") | S31: =IF(E31="","",SUM($O$14:O31)+SUM($P$14:P31)+SUM($Q$14:Q31)+SUM($R$14:R31)) | U31: 7.75 | V31: 欠勤 | Y31: 陳 | AE31: =SUM(H31,O31:R31)-SUM(T31:U31,AH31,AK31,AN31,AQ31) -> 0 | AR31: =SUM(AE31,AH31,AK31,AN31,AQ31) -> 0 | AS31: =IF(AR31=SUM($H31,$O31,$P31,$Q31,$R31,-$U31,-$T31),"合","不") -> 合 | AU31: =IF(AND(F31<>"",E31<>"",G31<>""),F31-E31-G31,"") | AV31: =IF(AND(D31="",AU31<>""),IF(F31>$AZ31,IF(F31>$AV$3,$AV$3-$AZ31,F31-$AZ31),""),"") | AW31: =IF(AND(D31="",F31>$AV$4),F31-$AV$4,"") | AX31: =IF(AND(D31="*",AU31<>""),AU31-IF(AY31<>"",AY31,0),"") | AY31: =IF(AND(D31="*",F31>$AV$4),F31-$AV$4,"") | AZ31: =IF(X31="B",$AW$2,IF(X31="C",$AX$2,$AV$2)) -> 0.75
B32: =IF(B31="","",IF(B31+1>Q$3,"",B31+1)) -> 46273 | C32: =IF(B32="","",CHOOSE(WEEKDAY(B32),"日","月","火","水","木","金","土")) -> 火 | E32: 0.375 | F32: 0.73958333 | G32: 0.041666667 | H32: 7.75 | O32: =IF(AV32<>"",HOUR(AV32)+MINUTE(AV32)/60,"") | P32: =IF(AW32<>"",HOUR(AW32)+MINUTE(AW32)/60,"") | Q32: =IF(AX32<>"",HOUR(AX32)+MINUTE(AX32)/60,"") | R32: =IF(AY32<>"",HOUR(AY32)+MINUTE(AY32)/60,"") | S32: =IF(E32="","",SUM($O$14:O32)+SUM($P$14:P32)+SUM($Q$14:Q32)+SUM($R$14:R32)) -> 0 | V32: デバイス制御資料の確認 | Y32: 陳 | AC32: 387605022 | AD32: タブレットPOS端末アプリ | AE32: =SUM(H32,O32:R32)-SUM(T32:U32,AH32,AK32,AN32,AQ32) -> 7.75 | AR32: =SUM(AE32,AH32,AK32,AN32,AQ32) -> 7.75 | AS32: =IF(AR32=SUM($H32,$O32,$P32,$Q32,$R32,-$U32,-$T32),"合","不") -> 合 | AU32: =IF(AND(F32<>"",E32<>"",G32<>""),F32-E32-G32,"") -> 0.32291667 | AV32: =IF(AND(D32="",AU32<>""),IF(F32>$AZ32,IF(F32>$AV$3,$AV$3-$AZ32,F32-$AZ32),""),"") | AW32: =IF(AND(D32="",F32>$AV$4),F32-$AV$4,"") | AX32: =IF(AND(D32="*",AU32<>""),AU32-IF(AY32<>"",AY32,0),"") | AY32: =IF(AND(D32="*",F32>$AV$4),F32-$AV$4,"") | AZ32: =IF(X32="B",$AW$2,IF(X32="C",$AX$2,$AV$2)) -> 0.75
B33: =IF(B32="","",IF(B32+1>Q$3,"",B32+1)) -> 46274 | C33: =IF(B33="","",CHOOSE(WEEKDAY(B33),"日","月","火","水","木","金","土")) -> 水 | E33: 0.375 | F33: 0.73958333 | G33: 0.041666667 | H33: 7.75 | O33: =IF(AV33<>"",HOUR(AV33)+MINUTE(AV33)/60,"") | P33: =IF(AW33<>"",HOUR(AW33)+MINUTE(AW33)/60,"") | Q33: =IF(AX33<>"",HOUR(AX33)+MINUTE(AX33)/60,"") | R33: =IF(AY33<>"",HOUR(AY33)+MINUTE(AY33)/60,"") | S33: =IF(E33="","",SUM($O$14:O33)+SUM($P$14:P33)+SUM($Q$14:Q33)+SUM($R$14:R33)) -> 0 | V33: デバイス制御資料の整理 | Y33: 陳 | AC33: 387605022 | AD33: タブレットPOS端末アプリ | AE33: =SUM(H33,O33:R33)-SUM(T33:U33,AH33,AK33,AN33,AQ33) -> 7.75 | AR33: =SUM(AE33,AH33,AK33,AN33,AQ33) -> 7.75 | AS33: =IF(AR33=SUM($H33,$O33,$P33,$Q33,$R33,-$U33,-$T33),"合","不") -> 合 | AU33: =IF(AND(F33<>"",E33<>"",G33<>""),F33-E33-G33,"") -> 0.32291667 | AV33: =IF(AND(D33="",AU33<>""),IF(F33>$AZ33,IF(F33>$AV$3,$AV$3-$AZ33,F33-$AZ33),""),"") | AW33: =IF(AND(D33="",F33>$AV$4),F33-$AV$4,"") | AX33: =IF(AND(D33="*",AU33<>""),AU33-IF(AY33<>"",AY33,0),"") | AY33: =IF(AND(D33="*",F33>$AV$4),F33-$AV$4,"") | AZ33: =IF(X33="B",$AW$2,IF(X33="C",$AX$2,$AV$2)) -> 0.75
B34: =IF(B33="","",IF(B33+1>Q$3,"",B33+1)) -> 46275 | C34: =IF(B34="","",CHOOSE(WEEKDAY(B34),"日","月","火","水","木","金","土")) -> 木 | E34: 0.375 | F34: 0.73958333 | G34: 0.041666667 | H34: 7.75 | O34: =IF(AV34<>"",HOUR(AV34)+MINUTE(AV34)/60,"") | P34: =IF(AW34<>"",HOUR(AW34)+MINUTE(AW34)/60,"") | Q34: =IF(AX34<>"",HOUR(AX34)+MINUTE(AX34)/60,"") | R34: =IF(AY34<>"",HOUR(AY34)+MINUTE(AY34)/60,"") | S34: =IF(E34="","",SUM($O$14:O34)+SUM($P$14:P34)+SUM($Q$14:Q34)+SUM($R$14:R34)) -> 0 | V34: デバイス制御設計書の作成 | Y34: 陳 | AC34: 387605022 | AD34: タブレットPOS端末アプリ | AE34: =SUM(H34,O34:R34)-SUM(T34:U34,AH34,AK34,AN34,AQ34) -> 7.75 | AR34: =SUM(AE34,AH34,AK34,AN34,AQ34) -> 7.75 | AS34: =IF(AR34=SUM($H34,$O34,$P34,$Q34,$R34,-$U34,-$T34),"合","不") -> 合 | AU34: =IF(AND(F34<>"",E34<>"",G34<>""),F34-E34-G34,"") -> 0.32291667 | AV34: =IF(AND(D34="",AU34<>""),IF(F34>$AZ34,IF(F34>$AV$3,$AV$3-$AZ34,F34-$AZ34),""),"") | AW34: =IF(AND(D34="",F34>$AV$4),F34-$AV$4,"") | AX34: =IF(AND(D34="*",AU34<>""),AU34-IF(AY34<>"",AY34,0),"") | AY34: =IF(AND(D34="*",F34>$AV$4),F34-$AV$4,"") | AZ34: =IF(X34="B",$AW$2,IF(X34="C",$AX$2,$AV$2)) -> 0.75
B35: =IF(B34="","",IF(B34+1>Q$3,"",B34+1)) -> 46276 | C35: =IF(B35="","",CHOOSE(WEEKDAY(B35),"日","月","火","水","木","金","土")) -> 金 | E35: 0.375 | F35: 0.73958333 | G35: 0.041666667 | H35: 7.75 | O35: =IF(AV35<>"",HOUR(AV35)+MINUTE(AV35)/60,"") | P35: =IF(AW35<>"",HOUR(AW35)+MINUTE(AW35)/60,"") | Q35: =IF(AX35<>"",HOUR(AX35)+MINUTE(AX35)/60,"") | R35: =IF(AY35<>"",HOUR(AY35)+MINUTE(AY35)/60,"") | S35: =IF(E35="","",SUM($O$14:O35)+SUM($P$14:P35)+SUM($Q$14:Q35)+SUM($R$14:R35)) -> 0 | V35: デバイス設定方式の確認 | Y35: 陳 | AC35: 387605022 | AD35: タブレットPOS端末アプリ | AE35: =SUM(H35,O35:R35)-SUM(T35:U35,AH35,AK35,AN35,AQ35) -> 7.75 | AR35: =SUM(AE35,AH35,AK35,AN35,AQ35) -> 7.75 | AS35: =IF(AR35=SUM($H35,$O35,$P35,$Q35,$R35,-$U35,-$T35),"合","不") -> 合 | AU35: =IF(AND(F35<>"",E35<>"",G35<>""),F35-E35-G35,"") -> 0.32291667 | AV35: =IF(AND(D35="",AU35<>""),IF(F35>$AZ35,IF(F35>$AV$3,$AV$3-$AZ35,F35-$AZ35),""),"") | AW35: =IF(AND(D35="",F35>$AV$4),F35-$AV$4,"") | AX35: =IF(AND(D35="*",AU35<>""),AU35-IF(AY35<>"",AY35,0),"") | AY35: =IF(AND(D35="*",F35>$AV$4),F35-$AV$4,"") | AZ35: =IF(X35="B",$AW$2,IF(X35="C",$AX$2,$AV$2)) -> 0.75
B36: =IF(B35="","",IF(B35+1>Q$3,"",B35+1)) -> 46277 | C36: =IF(B36="","",CHOOSE(WEEKDAY(B36),"日","月","火","水","木","金","土")) -> 土 | D36: * | O36: =IF(AV36<>"",HOUR(AV36)+MINUTE(AV36)/60,"") | P36: =IF(AW36<>"",HOUR(AW36)+MINUTE(AW36)/60,"") | Q36: =IF(AX36<>"",HOUR(AX36)+MINUTE(AX36)/60,"") | R36: =IF(AY36<>"",HOUR(AY36)+MINUTE(AY36)/60,"") | S36: =IF(E36="","",SUM($O$14:O36)+SUM($P$14:P36)+SUM($Q$14:Q36)+SUM($R$14:R36)) | AR36: =SUM(AE36,AH36,AK36,AN36,AQ36) -> 0 | AS36: =IF(AR36=SUM($H36,$O36,$P36,$Q36,$R36,-$U36,-$T36),"合","不") -> 合 | AU36: =IF(AND(F36<>"",E36<>"",G36<>""),F36-E36-G36,"") | AV36: =IF(AND(D36="",AU36<>""),IF(F36>$AZ36,IF(F36>$AV$3,$AV$3-$AZ36,F36-$AZ36),""),"") | AW36: =IF(AND(D36="",F36>$AV$4),F36-$AV$4,"") | AX36: =IF(AND(D36="*",AU36<>""),AU36-IF(AY36<>"",AY36,0),"") | AY36: =IF(AND(D36="*",F36>$AV$4),F36-$AV$4,"") | AZ36: =IF(X36="B",$AW$2,IF(X36="C",$AX$2,$AV$2)) -> 0.75
B37: =IF(B36="","",IF(B36+1>Q$3,"",B36+1)) -> 46278 | C37: =IF(B37="","",CHOOSE(WEEKDAY(B37),"日","月","火","水","木","金","土")) -> 日 | D37: * | O37: =IF(AV37<>"",HOUR(AV37)+MINUTE(AV37)/60,"") | P37: =IF(AW37<>"",HOUR(AW37)+MINUTE(AW37)/60,"") | Q37: =IF(AX37<>"",HOUR(AX37)+MINUTE(AX37)/60,"") | R37: =IF(AY37<>"",HOUR(AY37)+MINUTE(AY37)/60,"") | S37: =IF(E37="","",SUM($O$14:O37)+SUM($P$14:P37)+SUM($Q$14:Q37)+SUM($R$14:R37)) | AR37: =SUM(AE37,AH37,AK37,AN37,AQ37) -> 0 | AS37: =IF(AR37=SUM($H37,$O37,$P37,$Q37,$R37,-$U37,-$T37),"合","不") -> 合 | AU37: =IF(AND(F37<>"",E37<>"",G37<>""),F37-E37-G37,"") | AV37: =IF(AND(D37="",AU37<>""),IF(F37>$AZ37,IF(F37>$AV$3,$AV$3-$AZ37,F37-$AZ37),""),"") | AW37: =IF(AND(D37="",F37>$AV$4),F37-$AV$4,"") | AX37: =IF(AND(D37="*",AU37<>""),AU37-IF(AY37<>"",AY37,0),"") | AY37: =IF(AND(D37="*",F37>$AV$4),F37-$AV$4,"") | AZ37: =IF(X37="B",$AW$2,IF(X37="C",$AX$2,$AV$2)) -> 0.75
B38: =IF(B37="","",IF(B37+1>Q$3,"",B37+1)) -> 46279 | C38: =IF(B38="","",CHOOSE(WEEKDAY(B38),"日","月","火","水","木","金","土")) -> 月 | E38: 0.5625 | F38: 0.73958333 | G38: 0.041666667 | H38: 7.75 | O38: =IF(AV38<>"",HOUR(AV38)+MINUTE(AV38)/60,"") | P38: =IF(AW38<>"",HOUR(AW38)+MINUTE(AW38)/60,"") | Q38: =IF(AX38<>"",HOUR(AX38)+MINUTE(AX38)/60,"") | R38: =IF(AY38<>"",HOUR(AY38)+MINUTE(AY38)/60,"") | S38: =IF(E38="","",SUM($O$14:O38)+SUM($P$14:P38)+SUM($Q$14:Q38)+SUM($R$14:R38)) -> 0 | U38: 3.5 | V38: 午前欠勤、午後在宅、制御設計書作成 | Y38: 陳 | AC38: 387605022 | AD38: タブレットPOS端末アプリ | AE38: =SUM(H38,O38:R38)-SUM(T38:U38,AH38,AK38,AN38,AQ38) -> 4.25 | AR38: =SUM(AE38,AH38,AK38,AN38,AQ38) -> 4.25 | AS38: =IF(AR38=SUM($H38,$O38,$P38,$Q38,$R38,-$U38,-$T38),"合","不") -> 合 | AU38: =IF(AND(F38<>"",E38<>"",G38<>""),F38-E38-MAX(0,MIN(F38,TIME(13,30,0))-MAX(E38,TIME(12,30,0))),"") -> 0.17708333 | AV38: =IF(AND(D38="",AU38<>""),IF(F38>$AZ38,IF(F38>$AV$3,$AV$3-$AZ38,F38-$AZ38),""),"") | AW38: =IF(AND(D38="",F38>$AV$4),F38-$AV$4,"") | AX38: =IF(AND(D38="*",AU38<>""),AU38-IF(AY38<>"",AY38,0),"") | AY38: =IF(AND(D38="*",F38>$AV$4),F38-$AV$4,"") | AZ38: =IF(X38="B",$AW$2,IF(X38="C",$AX$2,$AV$2)) -> 0.75
B39: =IF(B38="","",IF(B38+1>Q$3,"",B38+1)) -> 46280 | C39: =IF(B39="","",CHOOSE(WEEKDAY(B39),"日","月","火","水","木","金","土")) -> 火 | E39: 0.375 | F39: 0.73958333 | G39: 0.041666667 | H39: 7.75 | O39: =IF(AV39<>"",HOUR(AV39)+MINUTE(AV39)/60,"") | P39: =IF(AW39<>"",HOUR(AW39)+MINUTE(AW39)/60,"") | Q39: =IF(AX39<>"",HOUR(AX39)+MINUTE(AX39)/60,"") | R39: =IF(AY39<>"",HOUR(AY39)+MINUTE(AY39)/60,"") | S39: =IF(E39="","",SUM($O$14:O39)+SUM($P$14:P39)+SUM($Q$14:Q39)+SUM($R$14:R39)) -> 0 | V39: デバイス制御設計書の作成 | Y39: 陳 | AC39: 387605022 | AD39: タブレットPOS端末アプリ | AE39: =SUM(H39,O39:R39)-SUM(T39:U39,AH39,AK39,AN39,AQ39) -> 7.75 | AR39: =SUM(AE39,AH39,AK39,AN39,AQ39) -> 7.75 | AS39: =IF(AR39=SUM($H39,$O39,$P39,$Q39,$R39,-$U39,-$T39),"合","不") -> 合 | AU39: =IF(AND(F39<>"",E39<>"",G39<>""),F39-E39-G39,"") -> 0.32291667 | AV39: =IF(AND(D39="",AU39<>""),IF(F39>$AZ39,IF(F39>$AV$3,$AV$3-$AZ39,F39-$AZ39),""),"") | AW39: =IF(AND(D39="",F39>$AV$4),F39-$AV$4,"") | AX39: =IF(AND(D39="*",AU39<>""),AU39-IF(AY39<>"",AY39,0),"") | AY39: =IF(AND(D39="*",F39>$AV$4),F39-$AV$4,"") | AZ39: =IF(X39="B",$AW$2,IF(X39="C",$AX$2,$AV$2)) -> 0.75
B40: =IF(B39="","",IF(B39+1>Q$3,"",B39+1)) -> 46281 | C40: =IF(B40="","",CHOOSE(WEEKDAY(B40),"日","月","火","水","木","金","土")) -> 水 | E40: 0.375 | F40: 0.73958333 | G40: 0.041666667 | H40: 7.75 | O40: =IF(AV40<>"",HOUR(AV40)+MINUTE(AV40)/60,"") | P40: =IF(AW40<>"",HOUR(AW40)+MINUTE(AW40)/60,"") | Q40: =IF(AX40<>"",HOUR(AX40)+MINUTE(AX40)/60,"") | R40: =IF(AY40<>"",HOUR(AY40)+MINUTE(AY40)/60,"") | S40: =IF(E40="","",SUM($O$14:O40)+SUM($P$14:P40)+SUM($Q$14:Q40)+SUM($R$14:R40)) -> 0 | V40: デバイス制御の説明資料作成 | Y40: 陳 | AC40: 387605022 | AD40: タブレットPOS端末アプリ | AE40: =SUM(H40,O40:R40)-SUM(T40:U40,AH40,AK40,AN40,AQ40) -> 7.75 | AR40: =SUM(AE40,AH40,AK40,AN40,AQ40) -> 7.75 | AS40: =IF(AR40=SUM($H40,$O40,$P40,$Q40,$R40,-$U40,-$T40),"合","不") -> 合 | AU40: =IF(AND(F40<>"",E40<>"",G40<>""),F40-E40-G40,"") -> 0.32291667 | AV40: =IF(AND(D40="",AU40<>""),IF(F40>$AZ40,IF(F40>$AV$3,$AV$3-$AZ40,F40-$AZ40),""),"") | AW40: =IF(AND(D40="",F40>$AV$4),F40-$AV$4,"") | AX40: =IF(AND(D40="*",AU40<>""),AU40-IF(AY40<>"",AY40,0),"") | AY40: =IF(AND(D40="*",F40>$AV$4),F40-$AV$4,"") | AZ40: =IF(X40="B",$AW$2,IF(X40="C",$AX$2,$AV$2)) -> 0.75
B41: =IF(B40="","",IF(B40+1>Q$3,"",B40+1)) -> 46282 | C41: =IF(B41="","",CHOOSE(WEEKDAY(B41),"日","月","火","水","木","金","土")) -> 木 | E41: 0.375 | F41: 0.73958333 | G41: 0.041666667 | H41: 7.75 | O41: =IF(AV41<>"",HOUR(AV41)+MINUTE(AV41)/60,"") | P41: =IF(AW41<>"",HOUR(AW41)+MINUTE(AW41)/60,"") | Q41: =IF(AX41<>"",HOUR(AX41)+MINUTE(AX41)/60,"") | R41: =IF(AY41<>"",HOUR(AY41)+MINUTE(AY41)/60,"") | S41: =IF(E41="","",SUM($O$14:O41)+SUM($P$14:P41)+SUM($Q$14:Q41)+SUM($R$14:R41)) -> 0 | V41: デバイス制御資料のレビュー | Y41: 陳 | AC41: 387605022 | AD41: タブレットPOS端末アプリ | AE41: =SUM(H41,O41:R41)-SUM(T41:U41,AH41,AK41,AN41,AQ41) -> 7.75 | AR41: =SUM(AE41,AH41,AK41,AN41,AQ41) -> 7.75 | AS41: =IF(AR41=SUM($H41,$O41,$P41,$Q41,$R41,-$U41,-$T41),"合","不") -> 合 | AU41: =IF(AND(F41<>"",E41<>"",G41<>""),F41-E41-G41,"") -> 0.32291667 | AV41: =IF(AND(D41="",AU41<>""),IF(F41>$AZ41,IF(F41>$AV$3,$AV$3-$AZ41,F41-$AZ41),""),"") | AW41: =IF(AND(D41="",F41>$AV$4),F41-$AV$4,"") | AX41: =IF(AND(D41="*",AU41<>""),AU41-IF(AY41<>"",AY41,0),"") | AY41: =IF(AND(D41="*",F41>$AV$4),F41-$AV$4,"") | AZ41: =IF(X41="B",$AW$2,IF(X41="C",$AX$2,$AV$2)) -> 0.75
...

Sheet 交通費明細
D1: シャープマーケティングジャパン株式会社 | I1: No.1/1
A2: 出 張 交 通 費 明 細 書 | E2: 所 属 | F2: ソリューション開発統轄部 企業システム開発部 第2開発センター
E3: 請求者 | F3: =パラメータ!B4 -> グエン ホン ソン | I3: 受領印
A5: 月/日 | B5: 外 出 時 間 | D5: 外 出 先 | E5: 交 通 費(含 電 話 料) | G5: 日 当 | H5: 宿 泊 | I5: 計 | J5: 案件コード
D6: （外 出 理 由） | E6: 明 細 | F6: 計 | J6: 距離
I7: =IF(F7="","",SUM(F7:H7))
I8: =F8 -> 0
I9: =IF(F9="","",SUM(F9:H9))
I11: =IF(F11="","",SUM(F11:H11))
I13: =IF(F13="","",SUM(F13:H13))
I15: =IF(F15="","",SUM(F15:H15))
I17: =IF(F17="","",SUM(F17:H17))
I19: =IF(F19="","",SUM(F19:H19))
I21: =IF(F21="","",SUM(F21:H21))
I23: =IF(F23="","",SUM(F23:H23))
I25: =IF(F25="","",SUM(F25:H25))
I27: =IF(F27="","",SUM(F27:H27))
I29: =IF(F29="","",SUM(F29:H29))
I31: =IF(F31="","",SUM(F31:H31))
... I47: =IF(F47="","",SUM(F47:H47))
A49: 小 計 | I49: =SUM(I7:I48) -> 0
F51: 統轄(次)長 | G51: 部 長 | H51: 課 長 | I51: 課 長

Sheet 請求内容入力シート
A1: 請求書 | J1: 構成比
A2: 日付 | B2: 46255 | F2: =IF(SUM(F4:F10)=P7,"OK","NG") -> OK | J2: 調整用 | K2: 就業管理台帳
A3: 区分 | B3: 名前 | C3: 案件コード | D3: ユーザー | E3: 案件名 | F3: 金額 | G3: 消費税 | H3: 合計 | I3: コード | J3: =SUM(J4:J10) -> 1 | K3: 構成比 | L3: 作業時間 | P3: =パラメータ!$B$4 -> グエン ホン ソン | Q3: ？ＭＡＮ
A4: 作業(通常) | B4: =IF(C4="","",$P$3) -> グエン ホン ソン | C4: 0387-605022 | D4: 株式会社 ケーズホールディングス | E4: タブレットPOS端末アプリ | F4: =IF(C4<>"",$P$7*J4,"") -> 400000 | I4: 401 | J4: 1 | K4: =VLOOKUP(C4,派遣管理台帳!$AC$73:$AF$82,4,FALSE) -> #N/A | L4: =VLOOKUP(C4,派遣管理台帳!$AC$73:$AE$82,3,FALSE) -> #N/A | O4: 固定 | P4: =派遣管理台帳!$AV$6 -> 400000 | Q4: =SUMIF($B$4:$B$17,Q3,$F$4:$F$17) -> 0
K5: =VLOOKUP(C5,派遣管理台帳!$AC$73:$AF$82,4,FALSE) -> 0 | L5: =VLOOKUP(C5,派遣管理台帳!$AC$73:$AE$82,3,FALSE) -> 0 | O5: 超過 | P5: =SUM(派遣管理台帳!$U$54:'派遣管理台帳'!$U$57) -> 0 | Q5: =SUMIF($B$4:$B$17,Q3,$G$4:$G$17) -> 0
K6: =VLOOKUP(C6,派遣管理台帳!$AC$73:$AF$82,4,FALSE) -> 0 | L6: =VLOOKUP(C6,派遣管理台帳!$AC$73:$AE$82,3,FALSE) -> 0 | O6: 控除 | P6: =SUM(派遣管理台帳!U58)*(-1) -> 0 | Q6: =SUMIF($B$4:$B$17,Q4,$H$4:$H$17) -> 0
B7: =IF(C7="","",$P$3) | F7: =IF(C7<>"",$P$7*J7,"") | K7: =VLOOKUP(C7,派遣管理台帳!$AC$73:$AF$82,4,FALSE) -> 0 | L7: =VLOOKUP(C7,派遣管理台帳!$AC$73:$AE$82,3,FALSE) -> 0 | O7: 請求額 | P7: =SUM(P4:P6) -> 400000 | Q7: =SUM(Q4:Q6) -> 0
B8: =IF(C8="","",$P$3) | F8: =IF(C8<>"",$P$7*J8,"") | K8: =VLOOKUP(C8,派遣管理台帳!$AC$73:$AF$82,4,FALSE) -> 0 | L8: =VLOOKUP(C8,派遣管理台帳!$AC$73:$AE$82,3,FALSE) -> 0 | O8: 合計（税抜） | Q8: =SUM(P7+Q7) -> 400000
B9: =IF(C9="","",$P$3) | F9: =IF(C9<>"",$P$7*J9,"") | K9: =VLOOKUP(C9,派遣管理台帳!$AC$73:$AF$82,4,FALSE) -> 0 | L9: =VLOOKUP(C9,派遣管理台帳!$AC$73:$AE$82,3,FALSE) -> 0 | O9: 消費税 | P9: 0.1 | Q9: =ROUND(Q8*P9,0) -> 40000
B10: =IF(C10="","",$P$3) | F10: =IF(C10<>"",$P$7*J10,"") | K10: =VLOOKUP(C10,派遣管理台帳!$AC$73:$AF$82,4,FALSE) -> 0 | L10: =VLOOKUP(C10,派遣管理台帳!$AC$73:$AE$82,3,FALSE) -> 0 | O10: 合計（税込） | Q10: =Q8+Q9 -> 440000
A11: 作業(保守) | B11: =IF(C11="","",$P$3) | G11: =IF(F11<>"",ROUND(F11*$P$9,0),"") | H11: =SUM(F11:G11) -> 0 | I11: 601
B12: =IF(C12="","",$P$3) | G12: =IF(F12<>"",ROUND(F12*$P$9,0),"") | H12: =SUM(F12:G12) -> 0 | O12: 保守期間
B13: =IF(C13="","",$P$3) | G13: =IF(F13<>"",ROUND(F13*$P$9,0),"") | H13: =SUM(F13:G13) -> 0 | O13: =YEAR($B$2)&RIGHT("00"&MONTH($B$2),2)&"01" -> 20260801 | P13: ～ | Q13: =YEAR($B$2)&RIGHT("00"&MONTH($B$2),2)&RIGHT("00"&DAY(DATE(YEAR($B$2),MONTH($B$2)+1,1)-1),2) -> 20260831
B14: =IF(C14="","",$P$3) | G14: =IF(F14<>"",ROUND(F14*$P$9,0),"") | H14: =SUM(F14:G14) -> 0
B15: =IF(C15="","",$P$3) | G15: =IF(F15<>"",ROUND(F15*$P$9,0),"") | H15: =SUM(F15:G15) -> 0
B16: =IF(C16="","",$P$3) | G16: =IF(F16<>"",ROUND(F16*$P$9,0),"") | H16: =SUM(F16:G16) -> 0
B17: =IF(C17="","",$P$3) | G17: =IF(F17<>"",ROUND(F17*$P$9,0),"") | H17: =SUM(F17:G17) -> 0
A18: 交通費(通常) | B18: =IF(C18="","",$P$3) | F18: =IF(J18<>0,J18,"") | I18: 409 | J18: =SUMIF(交通費明細!$J$7:$J$48,C18,交通費明細!$I$7:$I$48) -> 0 | O18: 区分別合計
B19: =IF(C19="","",$P$3) | F19: =IF(J19<>0,J19,"") | J19: =SUMIF(交通費明細!$J$7:$J$48,C19,交通費明細!$I$7:$I$48) -> 0 | O19: 作業(通常) | P19: =SUM(F4:F10) -> 400000
B20: =IF(C20="","",$P$3) | F20: =IF(J20<>0,J20,"") | J20: =SUMIF(交通費明細!$J$7:$J$48,C20,交通費明細!$I$7:$I$48) -> 0 | O20: 消費税 | P20: =ROUND(P19*P9,0) -> 40000 | Q20: 作業(通常)合計 | R20: =SUM(P19:P20) -> 440000
B21: =IF(C21="","",$P$3) | F21: =IF(J21<>0,J21,"") | J21: =SUMIF(交通費明細!$J$7:$J$48,C21,交通費明細!$I$7:$I$48) -> 0 | O21: 交通費(通常) | P21: =SUM(F18:F24) -> 0
B22: =IF(C22="","",$P$3) | F22: =IF(J22<>0,J22,"") | J22: =SUMIF(交通費明細!$J$7:$J$48,C22,交通費明細!$I$7:$I$48) -> 0 | O22: 消費税(0固定) | P22: 0 | Q22: 交通費(通常)合計 | R22: =SUM(P21:P22) -> 0
B23: =IF(C23="","",$P$3) | F23: =IF(J23<>0,J23,"") | J23: =SUMIF(交通費明細!$J$7:$J$48,C23,交通費明細!$I$7:$I$48) -> 0
B24: =IF(C24="","",$P$3) | F24: =IF(J24<>0,J24,"") | J24: =SUMIF(交通費明細!$J$7:$J$48,C24,交通費明細!$I$7:$I$48) -> 0
A25: 交通費(保守) | B25: =IF(C25="","",$P$3) | F25: =IF(J25<>0,J25,"") | G25: =IF(F25<>"",0,"") | H25: =SUM(F25:G25) -> 0 | I25: 609 | J25: =SUMIF(交通費明細!$J$7:$J$48,C25,交通費明細!$I$7:$I$48) -> 0 | O25: 作業(保守) | P25: =SUM(F11:F17) -> 0
B26: =IF(C26="","",$P$3) | F26: =IF(J26<>0,J26,"") | G26: =IF(F26<>"",0,"") | H26: =SUM(F26:G26) -> 0 | J26: =SUMIF(交通費明細!$J$7:$J$48,C26,交通費明細!$I$7:$I$48) -> 0 | O26: 消費税 | P26: =ROUND(P25*P9,0) -> 0 | Q26: 作業(保守)合計 | R26: =SUM(P25:P26) -> 0
B27: =IF(C27="","",$P$3) | F27: =IF(J27<>0,J27,"") | G27: =IF(F27<>"",0,"") | H27: =SUM(F27:G27) -> 0 | J27: =SUMIF(交通費明細!$J$7:$J$48,C27,交通費明細!$I$7:$I$48) -> 0 | O27: 交通費(保守) | P27: =SUM(F25:F31) -> 0
B28: =IF(C28="","",$P$3) | F28: =IF(J28<>0,J28,"") | G28: =IF(F28<>"",0,"") | H28: =SUM(F28:G28) -> 0 | J28: =SUMIF(交通費明細!$J$7:$J$48,C28,交通費明細!$I$7:$I$48) -> 0 | O28: 消費税(0固定) | P28: 0 | Q28: 交通費(保守)合計 | R28: =SUM(P27:P28) -> 0
B29: =IF(C29="","",$P$3) | F29: =IF(J29<>0,J29,"") | G29: =IF(F29<>"",0,"") | H29: =SUM(F29:G29) -> 0 | J29: =SUMIF(交通費明細!$J$7:$J$48,C29,交通費明細!$I$7:$I$48) -> 0
B30: =IF(C30="","",$P$3) | F30: =IF(J30<>0,J30,"") | G30: =IF(F30<>"",0,"") | H30: =SUM(F30:G30) -> 0 | J30: =SUMIF(交通費明細!$J$7:$J$48,C30,交通費明細!$I$7:$I$48) -> 0
B31: =IF(C31="","",$P$3) | F31: =IF(J31<>0,J31,"") | G31: =IF(F31<>"",0,"") | H31: =SUM(F31:G31) -> 0 | J31: =SUMIF(交通費明細!$J$7:$J$48,C31,交通費明細!$I$7:$I$48) -> 0
C33: 387051005 | D33: PGFL | E33: 受注活動
I34: 001/009

Sheet SDMINPUT_通常
AI1: =請求内容入力シート!B2 -> 46255 | AO1: 請求分
B3: SDM INPUT票
B5: 派遣社員 一括 | AG5: 外注先コード | AK5: =LEFT(パラメータ!B5,1) -> A | AL5: =MID(パラメータ!B5,2,1) -> 9 | AM5: =MID(パラメータ!B5,3,1) -> 7 | AN5: =MID(パラメータ!B5,4,1) -> 1 | AO5: =MID(パラメータ!B5,5,1) -> 2 | AP5: =MID(パラメータ!B5,6,1) -> 2
AG6: 外注先社名 | AK6: =パラメータ!B3 -> 株式会社VTIジャパン
AG7: 派遣社員名 | AK7: =パラメータ!B4 -> グエン ホン ソン
B12: No | C12: 部門コード | G12: システム受注番号 | R12: 顧客名 | AK12: 金 額
G13: 作業コード（3桁） | R13: システム名
B14: 1 | C14: =IF(G14<>"",パラメータ!$B$7,"") -> ５ＦＳＬ | G14: 0 | H14: 3 | I14: 8 | J14: 7 | K14: - | L14: 6 | M14: 0 | N14: 5 | O14: 0 | P14: 2 | Q14: 2 | R14: 株式会社 ケーズホールディングス タブレットPOS端末アプリ | AM14: 4 | AN14: 0 | AO14: 0 | AP14: 0 | AQ14: 0 | AR14: 0
G15: 401
B16: 2 | C16: =IF(G16<>"",パラメータ!$B$7,"") | G16: =IF(請求内容入力シート!$C$5<>"",LEFT(RIGHT("0000000000"&請求内容入力シート!$C$5,10),1),"") | H16: =IF(請求内容入力シート!$C$5<>"",LEFT(RIGHT("0000000000"&請求内容入力シート!$C$5,9),1),"") | I16: =IF(請求内容入力シート!$C$5<>"",LEFT(RIGHT("0000000000"&請求内容入力シート!$C$5,8),1),"") | J16: =IF(請求内容入力シート!$C$5<>"",LEFT(RIGHT("0000000000"&請求内容入力シート!$C$5,7),1),"") | K16: - | L16: =IF(請求内容入力シート!$C$5<>"",LEFT(RIGHT("0000000000"&請求内容入力シート!$C$5,6),1),"") | M16: =IF(請求内容入力シート!$C$5<>"",LEFT(RIGHT("0000000000"&請求内容入力シート!$C$5,5),1),"") | N16: =IF(請求内容入力シート!$C$5<>"",LEFT(RIGHT("0000000000"&請求内容入力シート!$C$5,4),1),"") | O16: =IF(請求内容入力シート!$C$5<>"",LEFT(RIGHT("0000000000"&請求内容入力シート!$C$5,3),1),"") | P16: =IF(請求内容入力シート!$C$5<>"",LEFT(RIGHT("0000000000"&請求内容入力シート!$C$5,2),1),"") | Q16: =IF(請求内容入力シート!$C$5<>"",LEFT(RIGHT("0000000000"&請求内容入力シート!$C$5,1),1),"") | R16: =IF(請求内容入力シート!$D$5<>"",請求内容入力シート!$D$5,"")
G17: =IF(請求内容入力シート!$I$5<>"",請求内容入力シート!$I$5,"") | R17: =IF(請求内容入力シート!$E$5<>"",請求内容入力シート!$E$5,"") | AK17: =IF(請求内容入力シート!$F$5<>"",LEFT(RIGHT(" "&請求内容入力シート!$F$5,8),1),"") | AL17: =IF(請求内容入力シート!$F$5<>"",LEFT(RIGHT(" "&請求内容入力シート!$F$5,7),1),"") | AM17: =IF(請求内容入力シート!$F$5<>"",LEFT(RIGHT(" "&請求内容入力シート!$F$5,6),1),"") | AN17: =IF(請求内容入力シート!$F$5<>"",LEFT(RIGHT(" "&請求内容入力シート!$F$5,5),1),"") | AO17: =IF(請求内容入力シート!$F$5<>"",LEFT(RIGHT(" "&請求内容入力シート!$F$5,4),1),"") | AP17: =IF(請求内容入力シート!$F$5<>"",LEFT(RIGHT(" "&請求内容入力シート!$F$5,3),1),"") | AQ17: =IF(請求内容入力シート!$F$5<>"",LEFT(RIGHT(" "&請求内容入力シート!$F$5,2),1),"") | AR17: =IF(請求内容入力シート!$F$5<>"",LEFT(RIGHT(" "&請求内容入力シート!$F$5,1),1),"")
B18: 3 | C18: =IF(G18<>"",パラメータ!$B$7,"") | G18: =IF(請求内容入力シート!$C$6<>"",LEFT(RIGHT("0000000000"&請求内容入力シート!$C$6,10),1),"") | H18: =IF(請求内容入力シート!$C$6<>"",LEFT(RIGHT("0000000000"&請求内容入力シート!$C$6,9),1),"") | I18: =IF(請求内容入力シート!$C$6<>"",LEFT(RIGHT("0000000000"&請求内容入力シート!$C$6,8),1),"") | J18: =IF(請求内容入力シート!$C$6<>"",LEFT(RIGHT("0000000000"&請求内容入力シート!$C$6,7),1),"") | K18: - | L18: =IF(請求内容入力シート!$C$6<>"",LEFT(RIGHT("0000000000"&請求内容入力シート!$C$6,6),1),"") | M18: =IF(請求内容入力シート!$C$6<>"",LEFT(RIGHT("0000000000"&請求内容入力シート!$C$6,5),1),"") | N18: =IF(請求内容入力シート!$C$6<>"",LEFT(RIGHT("0000000000"&請求内容入力シート!$C$6,4),1),"") | O18: =IF(請求内容入力シート!$C$6<>"",LEFT(RIGHT("0000000000"&請求内容入力シート!$C$6,3),1),"") | P18: =IF(請求内容入力シート!$C$6<>"",LEFT(RIGHT("0000000000"&請求内容入力シート!$C$6,2),1),"") | Q18: =IF(請求内容入力シート!$C$6<>"",LEFT(RIGHT("0000000000"&請求内容入力シート!$C$6,1),1),"") | R18: =IF(請求内容入力シート!$D$6<>"",請求内容入力シート!$D$6,"")
G19: =IF(請求内容入力シート!$I$6<>"",請求内容入力シート!$I$6,"") | R19: =IF(請求内容入力シート!$E$6<>"",請求内容入力シート!$E$6,"") | AK19: =IF(請求内容入力シート!$F$6<>"",LEFT(RIGHT(" "&請求内容入力シート!$F$6,8),1),"") | AL19: =IF(請求内容入力シート!$F$6<>"",LEFT(RIGHT(" "&請求内容入力シート!$F$6,7),1),"") | AM19: =IF(請求内容入力シート!$F$6<>"",LEFT(RIGHT(" "&請求内容入力シート!$F$6,6),1),"") | AN19: =IF(請求内容入力シート!$F$6<>"",LEFT(RIGHT(" "&請求内容入力シート!$F$6,5),1),"") | AO19: =IF(請求内容入力シート!$F$6<>"",LEFT(RIGHT(" "&請求内容入力シート!$F$6,4),1),"") | AP19: =IF(請求内容入力シート!$F$6<>"",LEFT(RIGHT(" "&請求内容入力シート!$F$6,3),1),"") | AQ19: =IF(請求内容入力シート!$F$6<>"",LEFT(RIGHT(" "&請求内容入力シート!$F$6,2),1),"") | AR19: =IF(請求内容入力シート!$F$6<>"",LEFT(RIGHT(" "&請求内容入力シート!$F$6,1),1),"")
B20: 4 | C20: =IF(G20<>"",パラメータ!$B$7,"") | G20: =IF(請求内容入力シート!$C$7<>"",LEFT(RIGHT("0000000000"&請求内容入力シート!$C$7,10),1),"") | H20: =IF(請求内容入力シート!$C$7<>"",LEFT(RIGHT("0000000000"&請求内容入力シート!$C$7,9),1),"") | I20: =IF(請求内容入力シート!$C$7<>"",LEFT(RIGHT("0000000000"&請求内容入力シート!$C$7,8),1),"") | J20: =IF(請求内容入力シート!$C$7<>"",LEFT(RIGHT("0000000000"&請求内容入力シート!$C$7,7),1),"") | K20: - | L20: =IF(請求内容入力シート!$C$7<>"",LEFT(RIGHT("0000000000"&請求内容入力シート!$C$7,6),1),"") | M20: =IF(請求内容入力シート!$C$7<>"",LEFT(RIGHT("0000000000"&請求内容入力シート!$C$7,5),1),"") | N20: =IF(請求内容入力シート!$C$7<>"",LEFT(RIGHT("0000000000"&請求内容入力シート!$C$7,4),1),"") | O20: =IF(請求内容入力シート!$C$7<>"",LEFT(RIGHT("0000000000"&請求内容入力シート!$C$7,3),1),"") | P20: =IF(請求内容入力シート!$C$7<>"",LEFT(RIGHT("0000000000"&請求内容入力シート!$C$7,2),1),"") | Q20: =IF(請求内容入力シート!$C$7<>"",LEFT(RIGHT("0000000000"&請求内容入力シート!$C$7,1),1),"") | R20: =IF(請求内容入力シート!$D$7<>"",請求内容入力シート!$D$7,"")
G21: =IF(請求内容入力シート!$I$7<>"",請求内容入力シート!$I$7,"") | R21: =IF(請求内容入力シート!$E$7<>"",請求内容入力シート!$E$7,"") | AK21: =IF(請求内容入力シート!$F$7<>"",LEFT(RIGHT(" "&請求内容入力シート!$F$7,8),1),"") | AL21: =IF(請求内容入力シート!$F$7<>"",LEFT(RIGHT(" "&請求内容入力シート!$F$7,7),1),"") | AM21: =IF(請求内容入力シート!$F$7<>"",LEFT(RIGHT(" "&請求内容入力シート!$F$7,6),1),"") | AN21: =IF(請求内容入力シート!$F$7<>"",LEFT(RIGHT(" "&請求内容入力シート!$F$7,5),1),"") | AO21: =IF(請求内容入力シート!$F$7<>"",LEFT(RIGHT(" "&請求内容入力シート!$F$7,4),1),"") | AP21: =IF(請求内容入力シート!$F$7<>"",LEFT(RIGHT(" "&請求内容入力シート!$F$7,3),1),"") | AQ21: =IF(請求内容入力シート!$F$7<>"",LEFT(RIGHT(" "&請求内容入力シート!$F$7,2),1),"") | AR21: =IF(請求内容入力シート!$F$7<>"",LEFT(RIGHT(" "&請求内容入力シート!$F$7,1),1),"")
B22: 5 | C22: =IF(G22<>"",パラメータ!$B$7,"") | G22: =IF(請求内容入力シート!$C$8<>"",LEFT(RIGHT("0000000000"&請求内容入力シート!$C$8,10),1),"") | H22: =IF(請求内容入力シート!$C$8<>"",LEFT(RIGHT("0000000000"&請求内容入力シート!$C$8,9),1),"") | I22: =IF(請求内容入力シート!$C$8<>"",LEFT(RIGHT("0000000000"&請求内容入力シート!$C$8,8),1),"") | J22: =IF(請求内容入力シート!$C$8<>"",LEFT(RIGHT("0000000000"&請求内容入力シート!$C$8,7),1),"") | K22: - | L22: =IF(請求内容入力シート!$C$8<>"",LEFT(RIGHT("0000000000"&請求内容入力シート!$C$8,6),1),"") | M22: =IF(請求内容入力シート!$C$8<>"",LEFT(RIGHT("0000000000"&請求内容入力シート!$C$8,5),1),"") | N22: =IF(請求内容入力シート!$C$8<>"",LEFT(RIGHT("0000000000"&請求内容入力シート!$C$8,4),1),"") | O22: =IF(請求内容入力シート!$C$8<>"",LEFT(RIGHT("0000000000"&請求内容入力シート!$C$8,3),1),"") | P22: =IF(請求内容入力シート!$C$8<>"",LEFT(RIGHT("0000000000"&請求内容入力シート!$C$8,2),1),"") | Q22: =IF(請求内容入力シート!$C$8<>"",LEFT(RIGHT("0000000000"&請求内容入力シート!$C$8,1),1),"") | R22: =IF(請求内容入力シート!$D$8<>"",請求内容入力シート!$D$8,"")
G23: =IF(請求内容入力シート!$I$8<>"",請求内容入力シート!$I$8,"") | R23: =IF(請求内容入力シート!$E$8<>"",請求内容入力シート!$E$8,"") | AK23: =IF(請求内容入力シート!$F$8<>"",LEFT(RIGHT(" "&請求内容入力シート!$F$8,8),1),"") | AL23: =IF(請求内容入力シート!$F$8<>"",LEFT(RIGHT(" "&請求内容入力シート!$F$8,7),1),"") | AM23: =IF(請求内容入力シート!$F$8<>"",LEFT(RIGHT(" "&請求内容入力シート!$F$8,6),1),"") | AN23: =IF(請求内容入力シート!$F$8<>"",LEFT(RIGHT(" "&請求内容入力シート!$F$8,5),1),"") | AO23: =IF(請求内容入力シート!$F$8<>"",LEFT(RIGHT(" "&請求内容入力シート!$F$8,4),1),"") | AP23: =IF(請求内容入力シート!$F$8<>"",LEFT(RIGHT(" "&請求内容入力シート!$F$8,3),1),"") | AQ23: =IF(請求内容入力シート!$F$8<>"",LEFT(RIGHT(" "&請求内容入力シート!$F$8,2),1),"") | AR23: =IF(請求内容入力シート!$F$8<>"",LEFT(RIGHT(" "&請求内容入力シート!$F$8,1),1),"")
B24: 6 | C24: =IF(G24<>"",パラメータ!$B$7,"") | G24: =IF(請求内容入力シート!$C$9<>"",LEFT(RIGHT("0000000000"&請求内容入力シート!$C$9,10),1),"") | H24: =IF(請求内容入力シート!$C$9<>"",LEFT(RIGHT("0000000000"&請求内容入力シート!$C$9,9),1),"") | I24: =IF(請求内容入力シート!$C$9<>"",LEFT(RIGHT("0000000000"&請求内容入力シート!$C$9,8),1),"") | J24: =IF(請求内容入力シート!$C$9<>"",LEFT(RIGHT("0000000000"&請求内容入力シート!$C$9,7),1),"") | K24: - | L24: =IF(請求内容入力シート!$C$9<>"",LEFT(RIGHT("0000000000"&請求内容入力シート!$C$9,6),1),"") | M24: =IF(請求内容入力シート!$C$9<>"",LEFT(RIGHT("0000000000"&請求内容入力シート!$C$9,5),1),"") | N24: =IF(請求内容入力シート!$C$9<>"",LEFT(RIGHT("0000000000"&請求内容入力シート!$C$9,4),1),"") | O24: =IF(請求内容入力シート!$C$9<>"",LEFT(RIGHT("0000000000"&請求内容入力シート!$C$9,3),1),"") | P24: =IF(請求内容入力シート!$C$9<>"",LEFT(RIGHT("0000000000"&請求内容入力シート!$C$9,2),1),"") | Q24: =IF(請求内容入力シート!$C$9<>"",LEFT(RIGHT("0000000000"&請求内容入力シート!$C$9,1),1),"") | R24: =IF(請求内容入力シート!$D$9<>"",請求内容入力シート!$D$9,"")
G25: =IF(請求内容入力シート!$I$9<>"",請求内容入力シート!$I$9,"") | R25: =IF(請求内容入力シート!$E$9<>"",請求内容入力シート!$E$9,"") | AK25: =IF(請求内容入力シート!$F$9<>"",LEFT(RIGHT(" "&請求内容入力シート!$F$9,8),1),"") | AL25: =IF(請求内容入力シート!$F$9<>"",LEFT(RIGHT(" "&請求内容入力シート!$F$9,7),1),"") | AM25: =IF(請求内容入力シート!$F$9<>"",LEFT(RIGHT(" "&請求内容入力シート!$F$9,6),1),"") | AN25: =IF(請求内容入力シート!$F$9<>"",LEFT(RIGHT(" "&請求内容入力シート!$F$9,5),1),"") | AO25: =IF(請求内容入力シート!$F$9<>"",LEFT(RIGHT(" "&請求内容入力シート!$F$9,4),1),"") | AP25: =IF(請求内容入力シート!$F$9<>"",LEFT(RIGHT(" "&請求内容入力シート!$F$9,3),1),"") | AQ25: =IF(請求内容入力シート!$F$9<>"",LEFT(RIGHT(" "&請求内容入力シート!$F$9,2),1),"") | AR25: =IF(請求内容入力シート!$F$9<>"",LEFT(RIGHT(" "&請求内容入力シート!$F$9,1),1),"")
B26: 7 | C26: =IF(G26<>"",パラメータ!$B$7,"") | G26: =IF(請求内容入力シート!$C$10<>"",LEFT(RIGHT("0000000000"&請求内容入力シート!$C$10,10),1),"") | H26: =IF(請求内容入力シート!$C$10<>"",LEFT(RIGHT("0000000000"&請求内容入力シート!$C$10,9),1),"") | I26: =IF(請求内容入力シート!$C$10<>"",LEFT(RIGHT("0000000000"&請求内容入力シート!$C$10,8),1),"") | J26: =IF(請求内容入力シート!$C$10<>"",LEFT(RIGHT("0000000000"&請求内容入力シート!$C$10,7),1),"") | K26: - | L26: =IF(請求内容入力シート!$C$10<>"",LEFT(RIGHT("0000000000"&請求内容入力シート!$C$10,6),1),"") | M26: =IF(請求内容入力シート!$C$10<>"",LEFT(RIGHT("0000000000"&請求内容入力シート!$C$10,5),1),"") | N26: =IF(請求内容入力シート!$C$10<>"",LEFT(RIGHT("0000000000"&請求内容入力シート!$C$10,4),1),"") | O26: =IF(請求内容入力シート!$C$10<>"",LEFT(RIGHT("0000000000"&請求内容入力シート!$C$10,3),1),"") | P26: =IF(請求内容入力シート!$C$10<>"",LEFT(RIGHT("0000000000"&請求内容入力シート!$C$10,2),1),"") | Q26: =IF(請求内容入力シート!$C$10<>"",LEFT(RIGHT("0000000000"&請求内容入力シート!$C$10,1),1),"") | R26: =IF(請求内容入力シート!$D$10<>"",請求内容入力シート!$D$10,"")
G27: =IF(請求内容入力シート!$I$10<>"",請求内容入力シート!$I$10,"") | R27: =IF(請求内容入力シート!$E$10<>"",請求内容入力シート!$E$10,"") | AK27: =IF(請求内容入力シート!$F$10<>"",LEFT(RIGHT(" "&請求内容入力シート!$F$10,8),1),"") | AL27: =IF(請求内容入力シート!$F$10<>"",LEFT(RIGHT(" "&請求内容入力シート!$F$10,7),1),"") | AM27: =IF(請求内容入力シート!$F$10<>"",LEFT(RIGHT(" "&請求内容入力シート!$F$10,6),1),"") | AN27: =IF(請求内容入力シート!$F$10<>"",LEFT(RIGHT(" "&請求内容入力シート!$F$10,5),1),"") | AO27: =IF(請求内容入力シート!$F$10<>"",LEFT(RIGHT(" "&請求内容入力シート!$F$10,4),1),"") | AP27: =IF(請求内容入力シート!$F$10<>"",LEFT(RIGHT(" "&請求内容入力シート!$F$10,3),1),"") | AQ27: =IF(請求内容入力シート!$F$10<>"",LEFT(RIGHT(" "&請求内容入力シート!$F$10,2),1),"") | AR27: =IF(請求内容入力シート!$F$10<>"",LEFT(RIGHT(" "&請求内容入力シート!$F$10,1),1),"")
AE28: 小 計 | AK28: =IF(請求内容入力シート!$P$19<>"",LEFT(RIGHT(" "&請求内容入力シート!$P$19,8),1),"") | AL28: =IF(請求内容入力シート!$P$19<>"",LEFT(RIGHT(" "&請求内容入力シート!$P$19,7),1),"") | AM28: =IF(請求内容入力シート!$P$19<>"",LEFT(RIGHT(" "&請求内容入力シート!$P$19,6),1),"") -> 4 | AN28: =IF(請求内容入力シート!$P$19<>"",LEFT(RIGHT(" "&請求内容入力シート!$P$19,5),1),"") -> 0 | AO28: =IF(請求内容入力シート!$P$19<>"",LEFT(RIGHT(" "&請求内容入力シート!$P$19,4),1),"") -> 0 | AP28: =IF(請求内容入力シート!$P$19<>"",LEFT(RIGHT(" "&請求内容入力シート!$P$19,3),1),"") -> 0 | AQ28: =IF(請求内容入力シート!$P$19<>"",LEFT(RIGHT(" "&請求内容入力シート!$P$19,2),1),"") -> 0 | AR28: =IF(請求内容入力シート!$P$19<>"",LEFT(RIGHT(" "&請求内容入力シート!$P$19,1),1),"") -> 0
B29: 備 考 | AE29: 消 費 税 等 | AK29: =IF(請求内容入力シート!$P$20<>"",LEFT(RIGHT(" "&請求内容入力シート!$P$20,8),1),"") | AL29: =IF(請求内容入力シート!$P$20<>"",LEFT(RIGHT(" "&請求内容入力シート!$P$20,7),1),"") | AM29: =IF(請求内容入力シート!$P$20<>"",LEFT(RIGHT(" "&請求内容入力シート!$P$20,6),1),"") | AN29: =IF(請求内容入力シート!$P$20<>"",LEFT(RIGHT(" "&請求内容入力シート!$P$20,5),1),"") -> 4 | AO29: =IF(請求内容入力シート!$P$20<>"",LEFT(RIGHT(" "&請求内容入力シート!$P$20,4),1),"") -> 0 | AP29: =IF(請求内容入力シート!$P$20<>"",LEFT(RIGHT(" "&請求内容入力シート!$P$20,3),1),"") -> 0 | AQ29: =IF(請求内容入力シート!$P$20<>"",LEFT(RIGHT(" "&請求内容入力シート!$P$20,2),1),"") -> 0 | AR29: =IF(請求内容入力シート!$P$20<>"",LEFT(RIGHT(" "&請求内容入力シート!$P$20,1),1),"") -> 0
C30: FIX | AE30: 合 計 | AK30: =IF(請求内容入力シート!$R$20<>"",LEFT(RIGHT(" "&請求内容入力シート!$R$20,8),1),"") | AL30: =IF(請求内容入力シート!$R$20<>"",LEFT(RIGHT(" "&請求内容入力シート!$R$20,7),1),"") | AM30: =IF(請求内容入力シート!$R$20<>"",LEFT(RIGHT(" "&請求内容入力シート!$R$20,6),1),"") -> 4 | AN30: =IF(請求内容入力シート!$R$20<>"",LEFT(RIGHT(" "&請求内容入力シート!$R$20,5),1),"") -> 4 | AO30: =IF(請求内容入力シート!$R$20<>"",LEFT(RIGHT(" "&請求内容入力シート!$R$20,4),1),"") -> 0 | AP30: =IF(請求内容入力シート!$R$20<>"",LEFT(RIGHT(" "&請求内容入力シート!$R$20,3),1),"") -> 0 | AQ30: =IF(請求内容入力シート!$R$20<>"",LEFT(RIGHT(" "&請求内容入力シート!$R$20,2),1),"") -> 0 | AR30: =IF(請求内容入力シート!$R$20<>"",LEFT(RIGHT(" "&請求内容入力シート!$R$20,1),1),"") -> 0
B42: 部門名 | E42: =パラメータ!B6 -> 企業システム開発部 第2開発センター
B43: 検印 | C43: 所長 | G43: 参事 | K43: 課長 | O43: 担当 | AK43: 見積番号
AK44: =パラメータ!$B$8&"01" -> C14101
AI48: =AI1 -> 46255 | AO48: 請求分
B50: SDM INPUT票（控）

Sheet SDMINPUT_通常(交通費)
AI1: =請求内容入力シート!B2 -> 46255 | AO1: 請求分
B3: SDM INPUT票
B5: 派遣社員（交通費） | AG5: 外注先コード | AK5: =LEFT(パラメータ!B5,1) -> A | AL5: =MID(パラメータ!B5,2,1) -> 9 | AM5: =MID(パラメータ!B5,3,1) -> 7 | AN5: =MID(パラメータ!B5,4,1) -> 1 | AO5: =MID(パラメータ!B5,5,1) -> 2 | AP5: =MID(パラメータ!B5,6,1) -> 2
AG6: 外注先社名 | AK6: =パラメータ!B3 -> 株式会社VTIジャパン
AG7: 派遣社員名 | AK7: =パラメータ!B4 -> グエン ホン ソン
B12: No | C12: 部門コード | G12: システム受注番号 | R12: 顧客名 | AK12: 金 額
G13: 作業コード（3桁） | R13: システム名
B14: 1 | C14: =IF(G14<>"",パラメータ!$B$7,"") | G14: =IF(請求内容入力シート!$C$18<>"",LEFT(RIGHT("0000000000"&請求内容入力シート!$C$18,10),1),"") | H14: =IF(請求内容入力シート!$C$18<>"",LEFT(RIGHT("0000000000"&請求内容入力シート!$C$18,9),1),"") | I14: =IF(請求内容入力シート!$C$18<>"",LEFT(RIGHT("0000000000"&請求内容入力シート!$C$18,8),1),"") | J14: =IF(請求内容入力シート!$C$18<>"",LEFT(RIGHT("0000000000"&請求内容入力シート!$C$18,7),1),"") | K14: - | L14: =IF(請求内容入力シート!$C$18<>"",LEFT(RIGHT("0000000000"&請求内容入力シート!$C$18,6),1),"") | M14: =IF(請求内容入力シート!$C$18<>"",LEFT(RIGHT("0000000000"&請求内容入力シート!$C$18,5),1),"") | N14: =IF(請求内容入力シート!$C$18<>"",LEFT(RIGHT("0000000000"&請求内容入力シート!$C$18,4),1),"") | O14: =IF(請求内容入力シート!$C$18<>"",LEFT(RIGHT("0000000000"&請求内容入力シート!$C$18,3),1),"") | P14: =IF(請求内容入力シート!$C$18<>"",LEFT(RIGHT("0000000000"&請求内容入力シート!$C$18,2),1),"") | Q14: =IF(請求内容入力シート!$C$18<>"",LEFT(RIGHT("0000000000"&請求内容入力シート!$C$18,1),1),"") | R14: =IF(請求内容入力シート!$D$18<>"",請求内容入力シート!$D$18,"")
G15: =IF(請求内容入力シート!$I$18<>"",請求内容入力シート!$I$18,"") -> 409 | R15: =IF(請求内容入力シート!$E$18<>"",請求内容入力シート!$E$18,"") | AK15: =IF(請求内容入力シート!$F$18<>"",LEFT(RIGHT(" "&請求内容入力シート!$F$18,8),1),"") | AL15: =IF(請求内容入力シート!$F$18<>"",LEFT(RIGHT(" "&請求内容入力シート!$F$18,7),1),"") | AM15: =IF(請求内容入力シート!$F$18<>"",LEFT(RIGHT(" "&請求内容入力シート!$F$18,6),1),"") | AN15: =IF(請求内容入力シート!$F$18<>"",LEFT(RIGHT(" "&請求内容入力シート!$F$18,5),1),"") | AO15: =IF(請求内容入力シート!$F$18<>"",LEFT(RIGHT(" "&請求内容入力シート!$F$18,4),1),"") | AP15: =IF(請求内容入力シート!$F$18<>"",LEFT(RIGHT(" "&請求内容入力シート!$F$18,3),1),"") | AQ15: =IF(請求内容入力シート!$F$18<>"",LEFT(RIGHT(" "&請求内容入力シート!$F$18,2),1),"") | AR15: =IF(請求内容入力シート!$F$18<>"",LEFT(RIGHT(" "&請求内容入力シート!$F$18,1),1),"")
B16: 2 | C16: =IF(G16<>"",パラメータ!$B$7,"") | G16: =IF(請求内容入力シート!$C$19<>"",LEFT(RIGHT("0000000000"&請求内容入力シート!$C$19,10),1),"") | H16: =IF(請求内容入力シート!$C$19<>"",LEFT(RIGHT("0000000000"&請求内容入力シート!$C$19,9),1),"") | I16: =IF(請求内容入力シート!$C$19<>"",LEFT(RIGHT("0000000000"&請求内容入力シート!$C$19,8),1),"") | J16: =IF(請求内容入力シート!$C$19<>"",LEFT(RIGHT("0000000000"&請求内容入力シート!$C$19,7),1),"") | K16: - | L16: =IF(請求内容入力シート!$C$19<>"",LEFT(RIGHT("0000000000"&請求内容入力シート!$C$19,6),1),"") | M16: =IF(請求内容入力シート!$C$19<>"",LEFT(RIGHT("0000000000"&請求内容入力シート!$C$19,5),1),"") | N16: =IF(請求内容入力シート!$C$19<>"",LEFT(RIGHT("0000000000"&請求内容入力シート!$C$19,4),1),"") | O16: =IF(請求内容入力シート!$C$19<>"",LEFT(RIGHT("0000000000"&請求内容入力シート!$C$19,3),1),"") | P16: =IF(請求内容入力シート!$C$19<>"",LEFT(RIGHT("0000000000"&請求内容入力シート!$C$19,2),1),"") | Q16: =IF(請求内容入力シート!$C$19<>"",LEFT(RIGHT("0000000000"&請求内容入力シート!$C$19,1),1),"") | R16: =IF(請求内容入力シート!$D$19<>"",請求内容入力シート!$D$19,"")
G17: =IF(請求内容入力シート!$I$19<>"",請求内容入力シート!$I$19,"") | R17: =IF(請求内容入力シート!$E$19<>"",請求内容入力シート!$E$19,"") | AK17: =IF(請求内容入力シート!$F$19<>"",LEFT(RIGHT(" "&請求内容入力シート!$F$19,8),1),"") | AL17: =IF(請求内容入力シート!$F$19<>"",LEFT(RIGHT(" "&請求内容入力シート!$F$19,7),1),"") | AM17: =IF(請求内容入力シート!$F$19<>"",LEFT(RIGHT(" "&請求内容入力シート!$F$19,6),1),"") | AN17: =IF(請求内容入力シート!$F$19<>"",LEFT(RIGHT(" "&請求内容入力シート!$F$19,5),1),"") | AO17: =IF(請求内容入力シート!$F$19<>"",LEFT(RIGHT(" "&請求内容入力シート!$F$19,4),1),"") | AP17: =IF(請求内容入力シート!$F$19<>"",LEFT(RIGHT(" "&請求内容入力シート!$F$19,3),1),"") | AQ17: =IF(請求内容入力シート!$F$19<>"",LEFT(RIGHT(" "&請求内容入力シート!$F$19,2),1),"") | AR17: =IF(請求内容入力シート!$F$19<>"",LEFT(RIGHT(" "&請求内容入力シート!$F$19,1),1),"")
B18: 3 | C18: =IF(G18<>"",パラメータ!$B$7,"") | G18: =IF(請求内容入力シート!$C$20<>"",LEFT(RIGHT("0000000000"&請求内容入力シート!$C$20,10),1),"") | H18: =IF(請求内容入力シート!$C$20<>"",LEFT(RIGHT("0000000000"&請求内容入力シート!$C$20,9),1),"") | I18: =IF(請求内容入力シート!$C$20<>"",LEFT(RIGHT("0000000000"&請求内容入力シート!$C$20,8),1),"") | J18: =IF(請求内容入力シート!$C$20<>"",LEFT(RIGHT("0000000000"&請求内容入力シート!$C$20,7),1),"") | K18: - | L18: =IF(請求内容入力シート!$C$20<>"",LEFT(RIGHT("0000000000"&請求内容入力シート!$C$20,6),1),"") | M18: =IF(請求内容入力シート!$C$20<>"",LEFT(RIGHT("0000000000"&請求内容入力シート!$C$20,5),1),"") | N18: =IF(請求内容入力シート!$C$20<>"",LEFT(RIGHT("0000000000"&請求内容入力シート!$C$20,4),1),"") | O18: =IF(請求内容入力シート!$C$20<>"",LEFT(RIGHT("0000000000"&請求内容入力シート!$C$20,3),1),"") | P18: =IF(請求内容入力シート!$C$20<>"",LEFT(RIGHT("0000000000"&請求内容入力シート!$C$20,2),1),"") | Q18: =IF(請求内容入力シート!$C$20<>"",LEFT(RIGHT("0000000000"&請求内容入力シート!$C$20,1),1),"") | R18: =IF(請求内容入力シート!$D$20<>"",請求内容入力シート!$D$20,"")
G19: =IF(請求内容入力シート!$I$20<>"",請求内容入力シート!$I$20,"") | R19: =IF(請求内容入力シート!$E$20<>"",請求内容入力シート!$E$20,"") | AK19: =IF(請求内容入力シート!$F$20<>"",LEFT(RIGHT(" "&請求内容入力シート!$F$20,8),1),"") | AL19: =IF(請求内容入力シート!$F$20<>"",LEFT(RIGHT(" "&請求内容入力シート!$F$20,7),1),"") | AM19: =IF(請求内容入力シート!$F$20<>"",LEFT(RIGHT(" "&請求内容入力シート!$F$20,6),1),"") | AN19: =IF(請求内容入力シート!$F$20<>"",LEFT(RIGHT(" "&請求内容入力シート!$F$20,5),1),"") | AO19: =IF(請求内容入力シート!$F$20<>"",LEFT(RIGHT(" "&請求内容入力シート!$F$20,4),1),"") | AP19: =IF(請求内容入力シート!$F$20<>"",LEFT(RIGHT(" "&請求内容入力シート!$F$20,3),1),"") | AQ19: =IF(請求内容入力シート!$F$20<>"",LEFT(RIGHT(" "&請求内容入力シート!$F$20,2),1),"") | AR19: =IF(請求内容入力シート!$F$20<>"",LEFT(RIGHT(" "&請求内容入力シート!$F$20,1),1),"")
B20: 4 | C20: =IF(G20<>"",パラメータ!$B$7,"") | G20: =IF(請求内容入力シート!$C$21<>"",LEFT(RIGHT("0000000000"&請求内容入力シート!$C$21,10),1),"") | H20: =IF(請求内容入力シート!$C$21<>"",LEFT(RIGHT("0000000000"&請求内容入力シート!$C$21,9),1),"") | I20: =IF(請求内容入力シート!$C$21<>"",LEFT(RIGHT("0000000000"&請求内容入力シート!$C$21,8),1),"") | J20: =IF(請求内容入力シート!$C$21<>"",LEFT(RIGHT("0000000000"&請求内容入力シート!$C$21,7),1),"") | K20: - | L20: =IF(請求内容入力シート!$C$21<>"",LEFT(RIGHT("0000000000"&請求内容入力シート!$C$21,6),1),"") | M20: =IF(請求内容入力シート!$C$21<>"",LEFT(RIGHT("0000000000"&請求内容入力シート!$C$21,5),1),"") | N20: =IF(請求内容入力シート!$C$21<>"",LEFT(RIGHT("0000000000"&請求内容入力シート!$C$21,4),1),"") | O20: =IF(請求内容入力シート!$C$21<>"",LEFT(RIGHT("0000000000"&請求内容入力シート!$C$21,3),1),"") | P20: =IF(請求内容入力シート!$C$21<>"",LEFT(RIGHT("0000000000"&請求内容入力シート!$C$21,2),1),"") | Q20: =IF(請求内容入力シート!$C$21<>"",LEFT(RIGHT("0000000000"&請求内容入力シート!$C$21,1),1),"") | R20: =IF(請求内容入力シート!$D$21<>"",請求内容入力シート!$D$21,"")
G21: =IF(請求内容入力シート!$I$21<>"",請求内容入力シート!$I$21,"") | R21: =IF(請求内容入力シート!$E$21<>"",請求内容入力シート!$E$21,"") | AK21: =IF(請求内容入力シート!$F$21<>"",LEFT(RIGHT(" "&請求内容入力シート!$F$21,8),1),"") | AL21: =IF(請求内容入力シート!$F$21<>"",LEFT(RIGHT(" "&請求内容入力シート!$F$21,7),1),"") | AM21: =IF(請求内容入力シート!$F$21<>"",LEFT(RIGHT(" "&請求内容入力シート!$F$21,6),1),"") | AN21: =IF(請求内容入力シート!$F$21<>"",LEFT(RIGHT(" "&請求内容入力シート!$F$21,5),1),"") | AO21: =IF(請求内容入力シート!$F$21<>"",LEFT(RIGHT(" "&請求内容入力シート!$F$21,4),1),"") | AP21: =IF(請求内容入力シート!$F$21<>"",LEFT(RIGHT(" "&請求内容入力シート!$F$21,3),1),"") | AQ21: =IF(請求内容入力シート!$F$21<>"",LEFT(RIGHT(" "&請求内容入力シート!$F$21,2),1),"") | AR21: =IF(請求内容入力シート!$F$21<>"",LEFT(RIGHT(" "&請求内容入力シート!$F$21,1),1),"")
B22: 5 | C22: =IF(G22<>"",パラメータ!$B$7,"") | G22: =IF(請求内容入力シート!$C$22<>"",LEFT(RIGHT("0000000000"&請求内容入力シート!$C$22,10),1),"") | H22: =IF(請求内容入力シート!$C$22<>"",LEFT(RIGHT("0000000000"&請求内容入力シート!$C$22,9),1),"") | I22: =IF(請求内容入力シート!$C$22<>"",LEFT(RIGHT("0000000000"&請求内容入力シート!$C$22,8),1),"") | J22: =IF(請求内容入力シート!$C$22<>"",LEFT(RIGHT("0000000000"&請求内容入力シート!$C$22,7),1),"") | K22: - | L22: =IF(請求内容入力シート!$C$22<>"",LEFT(RIGHT("0000000000"&請求内容入力シート!$C$22,6),1),"") | M22: =IF(請求内容入力シート!$C$22<>"",LEFT(RIGHT("0000000000"&請求内容入力シート!$C$22,5),1),"") | N22: =IF(請求内容入力シート!$C$22<>"",LEFT(RIGHT("0000000000"&請求内容入力シート!$C$22,4),1),"") | O22: =IF(請求内容入力シート!$C$22<>"",LEFT(RIGHT("0000000000"&請求内容入力シート!$C$22,3),1),"") | P22: =IF(請求内容入力シート!$C$22<>"",LEFT(RIGHT("0000000000"&請求内容入力シート!$C$22,2),1),"") | Q22: =IF(請求内容入力シート!$C$22<>"",LEFT(RIGHT("0000000000"&請求内容入力シート!$C$22,1),1),"") | R22: =IF(請求内容入力シート!$D$22<>"",請求内容入力シート!$D$22,"")
G23: =IF(請求内容入力シート!$I$22<>"",請求内容入力シート!$I$22,"") | R23: =IF(請求内容入力シート!$E$22<>"",請求内容入力シート!$E$22,"") | AK23: =IF(請求内容入力シート!$F$22<>"",LEFT(RIGHT(" "&請求内容入力シート!$F$22,8),1),"") | AL23: =IF(請求内容入力シート!$F$22<>"",LEFT(RIGHT(" "&請求内容入力シート!$F$22,7),1),"") | AM23: =IF(請求内容入力シート!$F$22<>"",LEFT(RIGHT(" "&請求内容入力シート!$F$22,6),1),"") | AN23: =IF(請求内容入力シート!$F$22<>"",LEFT(RIGHT(" "&請求内容入力シート!$F$22,5),1),"") | AO23: =IF(請求内容入力シート!$F$22<>"",LEFT(RIGHT(" "&請求内容入力シート!$F$22,4),1),"") | AP23: =IF(請求内容入力シート!$F$22<>"",LEFT(RIGHT(" "&請求内容入力シート!$F$22,3),1),"") | AQ23: =IF(請求内容入力シート!$F$22<>"",LEFT(RIGHT(" "&請求内容入力シート!$F$22,2),1),"") | AR23: =IF(請求内容入力シート!$F$22<>"",LEFT(RIGHT(" "&請求内容入力シート!$F$22,1),1),"")
B24: 6 | C24: =IF(G24<>"",パラメータ!$B$7,"") | G24: =IF(請求内容入力シート!$C$23<>"",LEFT(RIGHT("0000000000"&請求内容入力シート!$C$23,10),1),"") | H24: =IF(請求内容入力シート!$C$23<>"",LEFT(RIGHT("0000000000"&請求内容入力シート!$C$23,9),1),"") | I24: =IF(請求内容入力シート!$C$23<>"",LEFT(RIGHT("0000000000"&請求内容入力シート!$C$23,8),1),"") | J24: =IF(請求内容入力シート!$C$23<>"",LEFT(RIGHT("0000000000"&請求内容入力シート!$C$23,7),1),"") | K24: - | L24: =IF(請求内容入力シート!$C$23<>"",LEFT(RIGHT("0000000000"&請求内容入力シート!$C$23,6),1),"") | M24: =IF(請求内容入力シート!$C$23<>"",LEFT(RIGHT("0000000000"&請求内容入力シート!$C$23,5),1),"") | N24: =IF(請求内容入力シート!$C$23<>"",LEFT(RIGHT("0000000000"&請求内容入力シート!$C$23,4),1),"") | O24: =IF(請求内容入力シート!$C$23<>"",LEFT(RIGHT("0000000000"&請求内容入力シート!$C$23,3),1),"") | P24: =IF(請求内容入力シート!$C$23<>"",LEFT(RIGHT("0000000000"&請求内容入力シート!$C$23,2),1),"") | Q24: =IF(請求内容入力シート!$C$23<>"",LEFT(RIGHT("0000000000"&請求内容入力シート!$C$23,1),1),"") | R24: =IF(請求内容入力シート!$D$23<>"",請求内容入力シート!$D$23,"")
G25: =IF(請求内容入力シート!$I$23<>"",請求内容入力シート!$I$23,"") | R25: =IF(請求内容入力シート!$E$23<>"",請求内容入力シート!$E$23,"") | AK25: =IF(請求内容入力シート!$F$23<>"",LEFT(RIGHT(" "&請求内容入力シート!$F$23,8),1),"") | AL25: =IF(請求内容入力シート!$F$23<>"",LEFT(RIGHT(" "&請求内容入力シート!$F$23,7),1),"") | AM25: =IF(請求内容入力シート!$F$23<>"",LEFT(RIGHT(" "&請求内容入力シート!$F$23,6),1),"") | AN25: =IF(請求内容入力シート!$F$23<>"",LEFT(RIGHT(" "&請求内容入力シート!$F$23,5),1),"") | AO25: =IF(請求内容入力シート!$F$23<>"",LEFT(RIGHT(" "&請求内容入力シート!$F$23,4),1),"") | AP25: =IF(請求内容入力シート!$F$23<>"",LEFT(RIGHT(" "&請求内容入力シート!$F$23,3),1),"") | AQ25: =IF(請求内容入力シート!$F$23<>"",LEFT(RIGHT(" "&請求内容入力シート!$F$23,2),1),"") | AR25: =IF(請求内容入力シート!$F$23<>"",LEFT(RIGHT(" "&請求内容入力シート!$F$23,1),1),"")
B26: 7 | C26: =IF(G26<>"",パラメータ!$B$7,"") | G26: =IF(請求内容入力シート!$C$24<>"",LEFT(RIGHT("0000000000"&請求内容入力シート!$C$24,10),1),"") | H26: =IF(請求内容入力シート!$C$24<>"",LEFT(RIGHT("0000000000"&請求内容入力シート!$C$24,9),1),"") | I26: =IF(請求内容入力シート!$C$24<>"",LEFT(RIGHT("0000000000"&請求内容入力シート!$C$24,8),1),"") | J26: =IF(請求内容入力シート!$C$24<>"",LEFT(RIGHT("0000000000"&請求内容入力シート!$C$24,7),1),"") | K26: - | L26: =IF(請求内容入力シート!$C$24<>"",LEFT(RIGHT("0000000000"&請求内容入力シート!$C$24,6),1),"") | M26: =IF(請求内容入力シート!$C$24<>"",LEFT(RIGHT("0000000000"&請求内容入力シート!$C$24,5),1),"") | N26: =IF(請求内容入力シート!$C$24<>"",LEFT(RIGHT("0000000000"&請求内容入力シート!$C$24,4),1),"") | O26: =IF(請求内容入力シート!$C$24<>"",LEFT(RIGHT("0000000000"&請求内容入力シート!$C$24,3),1),"") | P26: =IF(請求内容入力シート!$C$24<>"",LEFT(RIGHT("0000000000"&請求内容入力シート!$C$24,2),1),"") | Q26: =IF(請求内容入力シート!$C$24<>"",LEFT(RIGHT("0000000000"&請求内容入力シート!$C$24,1),1),"") | R26: =IF(請求内容入力シート!$D$24<>"",請求内容入力シート!$D$24,"")
G27: =IF(請求内容入力シート!$I$24<>"",請求内容入力シート!$I$24,"") | R27: =IF(請求内容入力シート!$E$24<>"",請求内容入力シート!$E$24,"") | AK27: =IF(請求内容入力シート!$F$24<>"",LEFT(RIGHT(" "&請求内容入力シート!$F$24,8),1),"") | AL27: =IF(請求内容入力シート!$F$24<>"",LEFT(RIGHT(" "&請求内容入力シート!$F$24,7),1),"") | AM27: =IF(請求内容入力シート!$F$24<>"",LEFT(RIGHT(" "&請求内容入力シート!$F$24,6),1),"") | AN27: =IF(請求内容入力シート!$F$24<>"",LEFT(RIGHT(" "&請求内容入力シート!$F$24,5),1),"") | AO27: =IF(請求内容入力シート!$F$24<>"",LEFT(RIGHT(" "&請求内容入力シート!$F$24,4),1),"") | AP27: =IF(請求内容入力シート!$F$24<>"",LEFT(RIGHT(" "&請求内容入力シート!$F$24,3),1),"") | AQ27: =IF(請求内容入力シート!$F$24<>"",LEFT(RIGHT(" "&請求内容入力シート!$F$24,2),1),"") | AR27: =IF(請求内容入力シート!$F$24<>"",LEFT(RIGHT(" "&請求内容入力シート!$F$24,1),1),"")
AE28: 小 計 | AK28: =IF(請求内容入力シート!$P$21<>"",LEFT(RIGHT(" "&請求内容入力シート!$P$21,8),1),"") | AL28: =IF(請求内容入力シート!$P$21<>"",LEFT(RIGHT(" "&請求内容入力シート!$P$21,7),1),"") | AM28: =IF(請求内容入力シート!$P$21<>"",LEFT(RIGHT(" "&請求内容入力シート!$P$21,6),1),"") | AN28: =IF(請求内容入力シート!$P$21<>"",LEFT(RIGHT(" "&請求内容入力シート!$P$21,5),1),"") | AO28: =IF(請求内容入力シート!$P$21<>"",LEFT(RIGHT(" "&請求内容入力シート!$P$21,4),1),"") | AP28: =IF(請求内容入力シート!$P$21<>"",LEFT(RIGHT(" "&請求内容入力シート!$P$21,3),1),"") | AQ28: =IF(請求内容入力シート!$P$21<>"",LEFT(RIGHT(" "&請求内容入力シート!$P$21,2),1),"") | AR28: =IF(請求内容入力シート!$P$21<>"",LEFT(RIGHT(" "&請求内容入力シート!$P$21,1),1),"") -> 0
B29: 備 考 | AE29: 消 費 税 等 | AK29: =IF(請求内容入力シート!$P$22<>"",LEFT(RIGHT(" "&請求内容入力シート!$P$22,8),1),"") | AL29: =IF(請求内容入力シート!$P$22<>"",LEFT(RIGHT(" "&請求内容入力シート!$P$22,7),1),"") | AM29: =IF(請求内容入力シート!$P$22<>"",LEFT(RIGHT(" "&請求内容入力シート!$P$22,6),1),"") | AN29: =IF(請求内容入力シート!$P$22<>"",LEFT(RIGHT(" "&請求内容入力シート!$P$22,5),1),"") | AO29: =IF(請求内容入力シート!$P$22<>"",LEFT(RIGHT(" "&請求内容入力シート!$P$22,4),1),"") | AP29: =IF(請求内容入力シート!$P$22<>"",LEFT(RIGHT(" "&請求内容入力シート!$P$22,3),1),"") | AQ29: =IF(請求内容入力シート!$P$22<>"",LEFT(RIGHT(" "&請求内容入力シート!$P$22,2),1),"") | AR29: =IF(請求内容入力シート!$P$22<>"",LEFT(RIGHT(" "&請求内容入力シート!$P$22,1),1),"") -> 0
C30: ＦＩＸ交通費 | AE30: 合 計 | AK30: =IF(請求内容入力シート!$R$22<>"",LEFT(RIGHT(" "&請求内容入力シート!$R$22,8),1),"") | AL30: =IF(請求内容入力シート!$R$22<>"",LEFT(RIGHT(" "&請求内容入力シート!$R$22,7),1),"") | AM30: =IF(請求内容入力シート!$R$22<>"",LEFT(RIGHT(" "&請求内容入力シート!$R$22,6),1),"") | AN30: =IF(請求内容入力シート!$R$22<>"",LEFT(RIGHT(" "&請求内容入力シート!$R$22,5),1),"") | AO30: =IF(請求内容入力シート!$R$22<>"",LEFT(RIGHT(" "&請求内容入力シート!$R$22,4),1),"") | AP30: =IF(請求内容入力シート!$R$22<>"",LEFT(RIGHT(" "&請求内容入力シート!$R$22,3),1),"") | AQ30: =IF(請求内容入力シート!$R$22<>"",LEFT(RIGHT(" "&請求内容入力シート!$R$22,2),1),"") | AR30: =IF(請求内容入力シート!$R$22<>"",LEFT(RIGHT(" "&請求内容入力シート!$R$22,1),1),"") -> 0
B42: 部門名 | E42: =パラメータ!B6 -> 企業システム開発部 第2開発センター
B43: 検印 | C43: 所長 | G43: 参事 | K43: 課長 | O43: 担当 | AK43: 見積番号
AK44: =パラメータ!$B$8&"02" -> C14102
AI48: =AI1 -> 46255 | AO48: 請求分
B50: SDM INPUT票（控）

Sheet 保守①
B3: SDM INPUT票
B5: 派遣社員 保守 | AE5: 外注先コード | AI5: =LEFT(パラメータ!B5,1) -> A | AJ5: =MID(パラメータ!B5,2,1) -> 9 | AK5: =MID(パラメータ!B5,3,1) -> 7 | AL5: =MID(パラメータ!B5,4,1) -> 1 | AM5: =MID(パラメータ!B5,5,1) -> 2 | AN5: =MID(パラメータ!B5,6,1) -> 2
AE6: 外注先社名 | AI6: =パラメータ!B3 -> 株式会社VTIジャパン
AE7: 派遣社員名 | AI7: =パラメータ!B4 -> グエン ホン ソン
B12: No | C12: 部門コード | I12: システム受注番号 | T12: 顧客名 | AI12: 金 額
C13: 見積番号 | I13: 作業コード | T13: システム名
B14: 1 | C14: =IF(I14<>"",パラメータ!$B$7,"") | I14: =IF(請求内容入力シート!$C$11<>"",LEFT(RIGHT("0000000000"&請求内容入力シート!$C$11,10),1),"") | J14: =IF(請求内容入力シート!$C$11<>"",LEFT(RIGHT("0000000000"&請求内容入力シート!$C$11,9),1),"") | K14: =IF(請求内容入力シート!$C$11<>"",LEFT(RIGHT("0000000000"&請求内容入力シート!$C$11,8),1),"") | L14: =IF(請求内容入力シート!$C$11<>"",LEFT(RIGHT("0000000000"&請求内容入力シート!$C$11,7),1),"") | M14: - | N14: =IF(請求内容入力シート!$C$11<>"",LEFT(RIGHT("0000000000"&請求内容入力シート!$C$11,6),1),"") | O14: =IF(請求内容入力シート!$C$11<>"",LEFT(RIGHT("0000000000"&請求内容入力シート!$C$11,5),1),"") | P14: =IF(請求内容入力シート!$C$11<>"",LEFT(RIGHT("0000000000"&請求内容入力シート!$C$11,4),1),"") | Q14: =IF(請求内容入力シート!$C$11<>"",LEFT(RIGHT("0000000000"&請求内容入力シート!$C$11,3),1),"") | R14: =IF(請求内容入力シート!$C$11<>"",LEFT(RIGHT("0000000000"&請求内容入力シート!$C$11,2),1),"") | S14: =IF(請求内容入力シート!$C$11<>"",LEFT(RIGHT("0000000000"&請求内容入力シート!$C$11,1),1),"") | T14: =IF(請求内容入力シート!$D$11<>"",請求内容入力シート!$D$11,"")
C15: =IF(I14<>"",パラメータ!$B$8&"11","") | I15: ■ 6：ソフトサポート | O15: □ 9：交通費 | T15: =IF(請求内容入力シート!$E$11<>"",請求内容入力シート!$E$11,"") | AI15: =IF(請求内容入力シート!$F$11<>"",LEFT(RIGHT(" "&請求内容入力シート!$F$11,8),1),"") | AJ15: =IF(請求内容入力シート!$F$11<>"",LEFT(RIGHT(" "&請求内容入力シート!$F$11,7),1),"") | AK15: =IF(請求内容入力シート!$F$11<>"",LEFT(RIGHT(" "&請求内容入力シート!$F$11,6),1),"") | AL15: =IF(請求内容入力シート!$F$11<>"",LEFT(RIGHT(" "&請求内容入力シート!$F$11,5),1),"") | AM15: =IF(請求内容入力シート!$F$11<>"",LEFT(RIGHT(" "&請求内容入力シート!$F$11,4),1),"") | AN15: =IF(請求内容入力シート!$F$11<>"",LEFT(RIGHT(" "&請求内容入力シート!$F$11,3),1),"") | AO15: =IF(請求内容入力シート!$F$11<>"",LEFT(RIGHT(" "&請求内容入力シート!$F$11,2),1),"") | AP15: =IF(請求内容入力シート!$F$11<>"",LEFT(RIGHT(" "&請求内容入力シート!$F$11,1),1),"")
F16: （西暦） | AD16: 消 費 税 等 | AI16: =IF(請求内容入力シート!$G$11<>"",LEFT(RIGHT(" "&請求内容入力シート!$G$11,8),1),"") | AJ16: =IF(請求内容入力シート!$G$11<>"",LEFT(RIGHT(" "&請求内容入力シート!$G$11,7),1),"") | AK16: =IF(請求内容入力シート!$G$11<>"",LEFT(RIGHT(" "&請求内容入力シート!$G$11,6),1),"") | AL16: =IF(請求内容入力シート!$G$11<>"",LEFT(RIGHT(" "&請求内容入力シート!$G$11,5),1),"") | AM16: =IF(請求内容入力シート!$G$11<>"",LEFT(RIGHT(" "&請求内容入力シート!$G$11,4),1),"") | AN16: =IF(請求内容入力シート!$G$11<>"",LEFT(RIGHT(" "&請求内容入力シート!$G$11,3),1),"") | AO16: =IF(請求内容入力シート!$G$11<>"",LEFT(RIGHT(" "&請求内容入力シート!$G$11,2),1),"") | AP16: =IF(請求内容入力シート!$G$11<>"",LEFT(RIGHT(" "&請求内容入力シート!$G$11,1),1),"")
B17: 対応期間 | F17: =IF(請求内容入力シート!$C$11<>"",LEFT(RIGHT("00000000"&請求内容入力シート!$O$13,8),1),"") | G17: =IF(請求内容入力シート!$C$11<>"",LEFT(RIGHT("00000000"&請求内容入力シート!$O$13,7),1),"") | H17: =IF(請求内容入力シート!$C$11<>"",LEFT(RIGHT("00000000"&請求内容入力シート!$O$13,6),1),"") | I17: =IF(請求内容入力シート!$C$11<>"",LEFT(RIGHT("00000000"&請求内容入力シート!$O$13,5),1),"") | J17: 年 | K17: =IF(請求内容入力シート!$C$11<>"",LEFT(RIGHT("00000000"&請求内容入力シート!$O$13,4),1),"") | L17: =IF(請求内容入力シート!$C$11<>"",LEFT(RIGHT("00000000"&請求内容入力シート!$O$13,3),1),"") | M17: 月 | N17: =IF(請求内容入力シート!$C$11<>"",LEFT(RIGHT("00000000"&請求内容入力シート!$O$13,2),1),"") | O17: =IF(請求内容入力シート!$C$11<>"",LEFT(RIGHT("00000000"&請求内容入力シート!$O$13,1),1),"") | P17: 日 | Q17: ～ | R17: =IF(請求内容入力シート!$C$11<>"",LEFT(RIGHT("00000000"&請求内容入力シート!$Q$13,8),1),"") | S17: =IF(請求内容入力シート!$C$11<>"",LEFT(RIGHT("00000000"&請求内容入力シート!$Q$13,7),1),"") | T17: =IF(請求内容入力シート!$C$11<>"",LEFT(RIGHT("00000000"&請求内容入力シート!$Q$13,6),1),"") | U17: =IF(請求内容入力シート!$C$11<>"",LEFT(RIGHT("00000000"&請求内容入力シート!$Q$13,5),1),"") | V17: 年 | W17: =IF(請求内容入力シート!$C$11<>"",LEFT(RIGHT("00000000"&請求内容入力シート!$Q$13,4),1),"") | X17: =IF(請求内容入力シート!$C$11<>"",LEFT(RIGHT("00000000"&請求内容入力シート!$Q$13,3),1),"") | Y17: 月 | Z17: =IF(請求内容入力シート!$C$11<>"",LEFT(RIGHT("00000000"&請求内容入力シート!$Q$13,2),1),"") | AA17: =IF(請求内容入力シート!$C$11<>"",LEFT(RIGHT("00000000"&請求内容入力シート!$Q$13,1),1),"") | AB17: 日 | AD17: 合 計 | AI17: =IF(請求内容入力シート!$H$11<>"",LEFT(RIGHT(" "&請求内容入力シート!$H$11,8),1),"") | AJ17: =IF(請求内容入力シート!$H$11<>"",LEFT(RIGHT(" "&請求内容入力シート!$H$11,7),1),"") | AK17: =IF(請求内容入力シート!$H$11<>"",LEFT(RIGHT(" "&請求内容入力シート!$H$11,6),1),"") | AL17: =IF(請求内容入力シート!$H$11<>"",LEFT(RIGHT(" "&請求内容入力シート!$H$11,5),1),"") | AM17: =IF(請求内容入力シート!$H$11<>"",LEFT(RIGHT(" "&請求内容入力シート!$H$11,4),1),"") | AN17: =IF(請求内容入力シート!$H$11<>"",LEFT(RIGHT(" "&請求内容入力シート!$H$11,3),1),"") | AO17: =IF(請求内容入力シート!$H$11<>"",LEFT(RIGHT(" "&請求内容入力シート!$H$11,2),1),"") | AP17: =IF(請求内容入力シート!$H$11<>"",LEFT(RIGHT(" "&請求内容入力シート!$H$11,1),1),"") -> 0
B19: No | C19: 部門コード | I19: システム受注番号 | T19: 顧客名 | AI19: 金 額
C20: 見積番号 | I20: 作業コード | T20: システム名
